<?xml version="1.0" ?>
<robot name="gripkit_cr_plus_l_dd" xmlns:xacro="http://www.ros.org/wiki/xacro">

<xacro:include filename="$(find gripkit_cr_plus_l_dd_description)/urdf/gripkit_cr_plus_l_dd.trans" />
<xacro:include filename="$(find gripkit_cr_plus_l_dd_description)/urdf/gripkit_cr_plus_l_dd.gazebo" />

<link name="SF-ISO50-CRG200_Customer">
  <inertial>
    <origin xyz="-0.0008393872453184747 0.025000132684622287 0.005627799924905474" rpy="0 0 0"/>
    <mass value="0.16831092346442011"/>
    <inertia ixx="5.7e-05" iyy="0.000144" izz="0.000197" ixy="-0.0" iyz="0.0" ixz="1e-06"/>
  </inertial>
  <visual>
    <origin xyz="0.0 0.0252 -1.2665" rpy="0 0 0"/>
    <geometry>
      <mesh filename="package://gripkit_cr_plus_l_dd_description/meshes/SF-ISO50-CRG200_Customer.stl" scale="0.001 0.001 0.001"/>
    </geometry>
    <material name="silver"/>
  </visual>
  <collision>
    <origin xyz="0.0 0.0252 -1.2665" rpy="0 0 0"/>
    <geometry>
      <mesh filename="package://gripkit_cr_plus_l_dd_description/meshes/SF-ISO50-CRG200_Customer.stl" scale="0.001 0.001 0.001"/>
    </geometry>
  </collision>
</link>

<link name="CRG200_body">
  <inertial>
    <origin xyz="-0.04601341952229748 0.023500046460400284 0.029719376870479985" rpy="0 0 0"/>
    <mass value="1.024019455093708"/>
    <inertia ixx="0.000598" iyy="0.001224" izz="0.001229" ixy="0.0" iyz="-0.0" ixz="-0.0"/>
  </inertial>
  <visual>
    <origin xyz="-0.046 0.0237 -1.2775" rpy="0 0 0"/>
    <geometry>
      <mesh filename="package://gripkit_cr_plus_l_dd_description/meshes/CRG200_body.stl" scale="0.001 0.001 0.001"/>
    </geometry>
    <material name="silver"/>
  </visual>
  <collision>
    <origin xyz="-0.046 0.0237 -1.2775" rpy="0 0 0"/>
    <geometry>
      <mesh filename="package://gripkit_cr_plus_l_dd_description/meshes/CRG200_body.stl" scale="0.001 0.001 0.001"/>
    </geometry>
  </collision>
</link>

<link name="CRG200_base_jaw_1">
  <inertial>
    <origin xyz="-0.0011165967458195837 -1.0755285551056204e-16 0.004896836508835323" rpy="0 0 0"/>
    <mass value="0.028974809674202275"/>
    <inertia ixx="0.0" iyy="5e-06" izz="5e-06" ixy="0.0" iyz="-0.0" ixz="0.0"/>
  </inertial>
  <visual>
    <origin xyz="0.0 0.0187 -1.3351" rpy="0 0 0"/>
    <geometry>
      <mesh filename="package://gripkit_cr_plus_l_dd_description/meshes/CRG200_base_jaw_1.stl" scale="0.001 0.001 0.001"/>
    </geometry>
    <material name="silver"/>
  </visual>
  <collision>
    <origin xyz="0.0 0.0187 -1.3351" rpy="0 0 0"/>
    <geometry>
      <mesh filename="package://gripkit_cr_plus_l_dd_description/meshes/CRG200_base_jaw_1.stl" scale="0.001 0.001 0.001"/>
    </geometry>
  </collision>
</link>

<link name="CRG200_base_jaw_2">
  <inertial>
    <origin xyz="0.0011165967458171484 -7.979727989493313e-17 0.004896836508835323" rpy="0 0 0"/>
    <mass value="0.028974809674202275"/>
    <inertia ixx="0.0" iyy="5e-06" izz="5e-06" ixy="0.0" iyz="0.0" ixz="-0.0"/>
  </inertial>
  <visual>
    <origin xyz="0.0 -0.0183 -1.3351" rpy="0 0 0"/>
    <geometry>
      <mesh filename="package://gripkit_cr_plus_l_dd_description/meshes/CRG200_base_jaw_2.stl" scale="0.001 0.001 0.001"/>
    </geometry>
    <material name="silver"/>
  </visual>
  <collision>
    <origin xyz="0.0 -0.0183 -1.3351" rpy="0 0 0"/>
    <geometry>
      <mesh filename="package://gripkit_cr_plus_l_dd_description/meshes/CRG200_base_jaw_2.stl" scale="0.001 0.001 0.001"/>
    </geometry>
  </collision>
</link>

<link name="CRG200_top_cover">
  <inertial>
    <origin xyz="-2.837105234770214e-09 7.283818402294357e-09 0.004043925593782083" rpy="0 0 0"/>
    <mass value="0.117790703444327"/>
    <inertia ixx="3.5e-05" iyy="0.000112" izz="0.000144" ixy="-0.0" iyz="-0.0" ixz="0.0"/>
  </inertial>
  <visual>
    <origin xyz="0.0 0.0002 -1.3376" rpy="0 0 0"/>
    <geometry>
      <mesh filename="package://gripkit_cr_plus_l_dd_description/meshes/CRG200_top_cover.stl" scale="0.001 0.001 0.001"/>
    </geometry>
    <material name="silver"/>
  </visual>
  <collision>
    <origin xyz="0.0 0.0002 -1.3376" rpy="0 0 0"/>
    <geometry>
      <mesh filename="package://gripkit_cr_plus_l_dd_description/meshes/CRG200_top_cover.stl" scale="0.001 0.001 0.001"/>
    </geometry>
  </collision>
</link>

<link name="ISO_4762_-_M4_x_12ISO_1">
  <inertial>
    <origin xyz="-1.2420620087993939e-15 4.005129561335252e-13 0.0022480078452118413" rpy="0 0 0"/>
    <mass value="0.002203374250243251"/>
    <inertia ixx="0.0" iyy="0.0" izz="0.0" ixy="0.0" iyz="0.0" ixz="0.0"/>
  </inertial>
  <visual>
    <origin xyz="0.046 0.0237 -1.273" rpy="0 0 0"/>
    <geometry>
      <mesh filename="package://gripkit_cr_plus_l_dd_description/meshes/ISO_4762_-_M4_x_12ISO_1.stl" scale="0.001 0.001 0.001"/>
    </geometry>
    <material name="silver"/>
  </visual>
  <collision>
    <origin xyz="0.046 0.0237 -1.273" rpy="0 0 0"/>
    <geometry>
      <mesh filename="package://gripkit_cr_plus_l_dd_description/meshes/ISO_4762_-_M4_x_12ISO_1.stl" scale="0.001 0.001 0.001"/>
    </geometry>
  </collision>
</link>

<link name="ISO_4762_-_M4_x_12ISO_2">
  <inertial>
    <origin xyz="-1.2073675392798577e-15 4.005129561335252e-13 0.0022480078452118413" rpy="0 0 0"/>
    <mass value="0.002203374250243251"/>
    <inertia ixx="0.0" iyy="0.0" izz="0.0" ixy="0.0" iyz="0.0" ixz="0.0"/>
  </inertial>
  <visual>
    <origin xyz="-0.046 0.0237 -1.273" rpy="0 0 0"/>
    <geometry>
      <mesh filename="package://gripkit_cr_plus_l_dd_description/meshes/ISO_4762_-_M4_x_12ISO_2.stl" scale="0.001 0.001 0.001"/>
    </geometry>
    <material name="silver"/>
  </visual>
  <collision>
    <origin xyz="-0.046 0.0237 -1.273" rpy="0 0 0"/>
    <geometry>
      <mesh filename="package://gripkit_cr_plus_l_dd_description/meshes/ISO_4762_-_M4_x_12ISO_2.stl" scale="0.001 0.001 0.001"/>
    </geometry>
  </collision>
</link>

<link name="ISO_4762_-_M4_x_12ISO_3">
  <inertial>
    <origin xyz="-1.2073675392798577e-15 4.0054071170914085e-13 0.0022480078452118413" rpy="0 0 0"/>
    <mass value="0.002203374250243251"/>
    <inertia ixx="0.0" iyy="0.0" izz="0.0" ixy="0.0" iyz="0.0" ixz="0.0"/>
  </inertial>
  <visual>
    <origin xyz="-0.046 -0.0233 -1.273" rpy="0 0 0"/>
    <geometry>
      <mesh filename="package://gripkit_cr_plus_l_dd_description/meshes/ISO_4762_-_M4_x_12ISO_3.stl" scale="0.001 0.001 0.001"/>
    </geometry>
    <material name="silver"/>
  </visual>
  <collision>
    <origin xyz="-0.046 -0.0233 -1.273" rpy="0 0 0"/>
    <geometry>
      <mesh filename="package://gripkit_cr_plus_l_dd_description/meshes/ISO_4762_-_M4_x_12ISO_3.stl" scale="0.001 0.001 0.001"/>
    </geometry>
  </collision>
</link>

<link name="ISO_4762_-_M4_x_12ISO_4">
  <inertial>
    <origin xyz="-1.2420620087993939e-15 4.0054071170914085e-13 0.0022480078452118413" rpy="0 0 0"/>
    <mass value="0.002203374250243251"/>
    <inertia ixx="0.0" iyy="0.0" izz="0.0" ixy="0.0" iyz="0.0" ixz="0.0"/>
  </inertial>
  <visual>
    <origin xyz="0.046 -0.0233 -1.273" rpy="0 0 0"/>
    <geometry>
      <mesh filename="package://gripkit_cr_plus_l_dd_description/meshes/ISO_4762_-_M4_x_12ISO_4.stl" scale="0.001 0.001 0.001"/>
    </geometry>
    <material name="silver"/>
  </visual>
  <collision>
    <origin xyz="0.046 -0.0233 -1.273" rpy="0 0 0"/>
    <geometry>
      <mesh filename="package://gripkit_cr_plus_l_dd_description/meshes/ISO_4762_-_M4_x_12ISO_4.stl" scale="0.001 0.001 0.001"/>
    </geometry>
  </collision>
</link>

<link name="BE_20-030_CUSTOMER_v1_1">
  <inertial>
    <origin xyz="-0.01548587046158196 0.010207189127588083 0.004903018801766246" rpy="0 0 0"/>
    <mass value="0.07101056528211638"/>
    <inertia ixx="7e-06" iyy="8e-06" izz="1.4e-05" ixy="4e-06" iyz="-0.0" ixz="0.0"/>
  </inertial>
  <visual>
    <origin xyz="0.002 0.0187 -1.3475" rpy="0 0 0"/>
    <geometry>
      <mesh filename="package://gripkit_cr_plus_l_dd_description/meshes/BE_20-030_CUSTOMER_v1_1.stl" scale="0.001 0.001 0.001"/>
    </geometry>
    <material name="silver"/>
  </visual>
  <collision>
    <origin xyz="0.002 0.0187 -1.3475" rpy="0 0 0"/>
    <geometry>
      <mesh filename="package://gripkit_cr_plus_l_dd_description/meshes/BE_20-030_CUSTOMER_v1_1.stl" scale="0.001 0.001 0.001"/>
    </geometry>
  </collision>
</link>

<link name="BE_20-030_CUSTOMER_v1_2">
  <inertial>
    <origin xyz="0.015485870461579518 -0.01020718912758825 0.004903018801766246" rpy="0 0 0"/>
    <mass value="0.07101056528211638"/>
    <inertia ixx="7e-06" iyy="8e-06" izz="1.4e-05" ixy="4e-06" iyz="0.0" ixz="-0.0"/>
  </inertial>
  <visual>
    <origin xyz="-0.002 -0.0183 -1.3475" rpy="0 0 0"/>
    <geometry>
      <mesh filename="package://gripkit_cr_plus_l_dd_description/meshes/BE_20-030_CUSTOMER_v1_2.stl" scale="0.001 0.001 0.001"/>
    </geometry>
    <material name="silver"/>
  </visual>
  <collision>
    <origin xyz="-0.002 -0.0183 -1.3475" rpy="0 0 0"/>
    <geometry>
      <mesh filename="package://gripkit_cr_plus_l_dd_description/meshes/BE_20-030_CUSTOMER_v1_2.stl" scale="0.001 0.001 0.001"/>
    </geometry>
  </collision>
</link>

<link name="FE_20-050_CUSTOMER_v1_1">
  <inertial>
    <origin xyz="-0.024908407665589435 -1.1511516566364843e-16 6.768003808832468e-05" rpy="0 0 0"/>
    <mass value="0.11001397809346045"/>
    <inertia ixx="8e-06" iyy="4.5e-05" izz="4.4e-05" ixy="0.0" iyz="0.0" ixz="-7e-06"/>
  </inertial>
  <visual>
    <origin xyz="0.027 0.0002 -1.3575" rpy="0 0 0"/>
    <geometry>
      <mesh filename="package://gripkit_cr_plus_l_dd_description/meshes/FE_20-050_CUSTOMER_v1_1.stl" scale="0.001 0.001 0.001"/>
    </geometry>
    <material name="silver"/>
  </visual>
  <collision>
    <origin xyz="0.027 0.0002 -1.3575" rpy="0 0 0"/>
    <geometry>
      <mesh filename="package://gripkit_cr_plus_l_dd_description/meshes/FE_20-050_CUSTOMER_v1_1.stl" scale="0.001 0.001 0.001"/>
    </geometry>
  </collision>
</link>

<link name="FE_20-050_CUSTOMER_v1_2">
  <inertial>
    <origin xyz="0.02490840766558711 -8.058332646998512e-17 6.768003808832468e-05" rpy="0 0 0"/>
    <mass value="0.11001397809346045"/>
    <inertia ixx="8e-06" iyy="4.5e-05" izz="4.4e-05" ixy="0.0" iyz="-0.0" ixz="7e-06"/>
  </inertial>
  <visual>
    <origin xyz="-0.027 0.0002 -1.3575" rpy="0 0 0"/>
    <geometry>
      <mesh filename="package://gripkit_cr_plus_l_dd_description/meshes/FE_20-050_CUSTOMER_v1_2.stl" scale="0.001 0.001 0.001"/>
    </geometry>
    <material name="silver"/>
  </visual>
  <collision>
    <origin xyz="-0.027 0.0002 -1.3575" rpy="0 0 0"/>
    <geometry>
      <mesh filename="package://gripkit_cr_plus_l_dd_description/meshes/FE_20-050_CUSTOMER_v1_2.stl" scale="0.001 0.001 0.001"/>
    </geometry>
  </collision>
</link>

<link name="AC_20-025_CUSTOMER_v1_1">
  <inertial>
    <origin xyz="-0.0019437600342800815 -1.0879968800892037e-16 0.01432838830627281" rpy="0 0 0"/>
    <mass value="0.07018824497649055"/>
    <inertia ixx="9e-06" iyy="9e-06" izz="4e-06" ixy="-0.0" iyz="-0.0" ixz="1e-06"/>
  </inertial>
  <visual>
    <origin xyz="0.077 0.0002 -1.3575" rpy="0 0 0"/>
    <geometry>
      <mesh filename="package://gripkit_cr_plus_l_dd_description/meshes/AC_20-025_CUSTOMER_v1_1.stl" scale="0.001 0.001 0.001"/>
    </geometry>
    <material name="silver"/>
  </visual>
  <collision>
    <origin xyz="0.077 0.0002 -1.3575" rpy="0 0 0"/>
    <geometry>
      <mesh filename="package://gripkit_cr_plus_l_dd_description/meshes/AC_20-025_CUSTOMER_v1_1.stl" scale="0.001 0.001 0.001"/>
    </geometry>
  </collision>
</link>

<link name="AC_20-025_CUSTOMER_v1_2">
  <inertial>
    <origin xyz="0.0019437600342755712 -8.353777739000812e-17 0.014328388306273032" rpy="0 0 0"/>
    <mass value="0.07018824497649055"/>
    <inertia ixx="9e-06" iyy="9e-06" izz="4e-06" ixy="-0.0" iyz="0.0" ixz="-1e-06"/>
  </inertial>
  <visual>
    <origin xyz="-0.077 0.0002 -1.3575" rpy="0 0 0"/>
    <geometry>
      <mesh filename="package://gripkit_cr_plus_l_dd_description/meshes/AC_20-025_CUSTOMER_v1_2.stl" scale="0.001 0.001 0.001"/>
    </geometry>
    <material name="silver"/>
  </visual>
  <collision>
    <origin xyz="-0.077 0.0002 -1.3575" rpy="0 0 0"/>
    <geometry>
      <mesh filename="package://gripkit_cr_plus_l_dd_description/meshes/AC_20-025_CUSTOMER_v1_2.stl" scale="0.001 0.001 0.001"/>
    </geometry>
  </collision>
</link>

<link name="FT_20-UNI_CUSTOMER_v1_1">
  <inertial>
    <origin xyz="0.009779007136433954 -2.2445451530392346e-14 6.0466063424691185e-05" rpy="0 0 0"/>
    <mass value="0.05314853137521012"/>
    <inertia ixx="3e-06" iyy="3e-06" izz="3e-06" ixy="-0.0" iyz="0.0" ixz="-0.0"/>
  </inertial>
  <visual>
    <origin xyz="0.077 0.0002 -1.3825" rpy="0 0 0"/>
    <geometry>
      <mesh filename="package://gripkit_cr_plus_l_dd_description/meshes/FT_20-UNI_CUSTOMER_v1_1.stl" scale="0.001 0.001 0.001"/>
    </geometry>
    <material name="silver"/>
  </visual>
  <collision>
    <origin xyz="0.077 0.0002 -1.3825" rpy="0 0 0"/>
    <geometry>
      <mesh filename="package://gripkit_cr_plus_l_dd_description/meshes/FT_20-UNI_CUSTOMER_v1_1.stl" scale="0.001 0.001 0.001"/>
    </geometry>
  </collision>
</link>

<link name="FT_20-UNI_CUSTOMER_v1_2">
  <inertial>
    <origin xyz="-0.009779007136440115 2.224679858733869e-14 6.046606342335892e-05" rpy="0 0 0"/>
    <mass value="0.05314853137521012"/>
    <inertia ixx="3e-06" iyy="3e-06" izz="3e-06" ixy="-0.0" iyz="-0.0" ixz="0.0"/>
  </inertial>
  <visual>
    <origin xyz="-0.077 0.0002 -1.3825" rpy="0 0 0"/>
    <geometry>
      <mesh filename="package://gripkit_cr_plus_l_dd_description/meshes/FT_20-UNI_CUSTOMER_v1_2.stl" scale="0.001 0.001 0.001"/>
    </geometry>
    <material name="silver"/>
  </visual>
  <collision>
    <origin xyz="-0.077 0.0002 -1.3825" rpy="0 0 0"/>
    <geometry>
      <mesh filename="package://gripkit_cr_plus_l_dd_description/meshes/FT_20-UNI_CUSTOMER_v1_2.stl" scale="0.001 0.001 0.001"/>
    </geometry>
  </collision>
</link>

<joint name="Rigid08" type="fixed">
  <origin xyz="0.046 0.0015 0.011" rpy="0 0 0"/>
  <parent link="SF-ISO50-CRG200_Customer"/>
  <child link="CRG200_body"/>
</joint>

<joint name="Slider01" type="prismatic">
  <origin xyz="-0.046 0.005 0.0576" rpy="0 0 0"/>
  <parent link="CRG200_body"/>
  <child link="CRG200_base_jaw_1"/>
  <axis xyz="1.0 0.0 0.0"/>
  <limit upper="0.021" lower="-0.021" effort="100" velocity="100"/>
</joint>

<joint name="Slider02" type="prismatic">
  <origin xyz="-0.046 0.042 0.0576" rpy="0 0 0"/>
  <parent link="CRG200_body"/>
  <child link="CRG200_base_jaw__1__1"/>
  <axis xyz="1.0 0.0 0.0"/>
  <limit upper="0.021" lower="-0.021" effort="100" velocity="100"/>
</joint>

<joint name="Rigid09" type="fixed">
  <origin xyz="-0.046 0.0235 0.0601" rpy="0 0 0"/>
  <parent link="CRG200_body"/>
  <child link="CRG200_top_cover"/>
</joint>

<joint name="Rigid10" type="fixed">
  <origin xyz="-0.046 0.0015 0.0065" rpy="0 0 0"/>
  <parent link="SF-ISO50-CRG200_Customer"/>
  <child link="ISO_4762_-_M4_x_12ISO_1"/>
</joint>

<joint name="Rigid11" type="fixed">
  <origin xyz="0.046 0.0015 0.0065" rpy="0 0 0"/>
  <parent link="SF-ISO50-CRG200_Customer"/>
  <child link="ISO_4762_-_M4_x_12ISO_2"/>
</joint>

<joint name="Rigid12" type="fixed">
  <origin xyz="0.046 0.0485 0.0065" rpy="0 0 0"/>
  <parent link="SF-ISO50-CRG200_Customer"/>
  <child link="ISO_4762_-_M4_x_12ISO_3"/>
</joint>

<joint name="Rigid13" type="fixed">
  <origin xyz="-0.046 0.0485 0.0065" rpy="0 0 0"/>
  <parent link="SF-ISO50-CRG200_Customer"/>
  <child link="ISO_4762_-_M4_x_12ISO_4"/>
</joint>

<joint name="Rigid14" type="fixed">
  <origin xyz="-0.002 0.0 0.0124" rpy="0 0 0"/>
  <parent link="CRG200_base_jaw_1"/>
  <child link="BE_20-030_CUSTOMER_v1_1"/>
</joint>

<joint name="Rigid15" type="fixed">
  <origin xyz="0.002 0.0 0.0124" rpy="0 0 0"/>
  <parent link="CRG200_base_jaw_2"/>
  <child link="BE_20-030_CUSTOMER_v1_2"/>
</joint>

<joint name="Rigid16" type="fixed">
  <origin xyz="-0.025 0.0185 0.01" rpy="0 0 0"/>
  <parent link="BE_20-030_CUSTOMER_v1_1"/>
  <child link="FE_20-050_CUSTOMER_v1_1"/>
</joint>

<joint name="Rigid17" type="fixed">
  <origin xyz="0.025 -0.0185 0.01" rpy="0 0 0"/>
  <parent link="BE_20-030_CUSTOMER_v1_2"/>
  <child link="FE_20-050_CUSTOMER_v1_2"/>
</joint>

<joint name="Rigid18" type="fixed">
  <origin xyz="-0.05 0.0 0.0" rpy="0 0 0"/>
  <parent link="FE_20-050_CUSTOMER_v1_1"/>
  <child link="AC_20-025_CUSTOMER_v1_1"/>
</joint>

<joint name="Rigid19" type="fixed">
  <origin xyz="0.05 0.0 0.0" rpy="0 0 0"/>
  <parent link="FE_20-050_CUSTOMER_v1_2"/>
  <child link="AC_20-025_CUSTOMER_v1_2"/>
</joint>

<joint name="Rigid20" type="fixed">
  <origin xyz="0.0 0.0 0.025" rpy="0 0 0"/>
  <parent link="AC_20-025_CUSTOMER_v1_1"/>
  <child link="FT_20-UNI_CUSTOMER_v1_1"/>
</joint>

<joint name="Rigid21" type="fixed">
  <origin xyz="0.0 0.0 0.025" rpy="0 0 0"/>
  <parent link="AC_20-025_CUSTOMER_v1_2"/>
  <child link="FT_20-UNI_CUSTOMER_v1_2"/>
</joint>

</robot>
