<?xml version="1.0" ?>
<robot name="gripkit_cr_plus_l_dd" xmlns:xacro="http://www.ros.org/wiki/xacro">

<xacro:include filename="$(find gripkit_cr_plus_l_dd_description)/urdf/gripkit_cr_plus_l_dd.trans" />
<xacro:include filename="$(find gripkit_cr_plus_l_dd_description)/urdf/gripkit_cr_plus_l_dd.gazebo" />

<xacro:property name="max_velocity" value="10"/>
<xacro:property name="max_effort" value="100"/>

<link name="SF-ISO50-CRG200_Customer">
  <inertial>
    <origin xyz="-0.000839387245317249 1.3268462236734284e-07 0.0056277999249054874" rpy="0 0 0"/>
    <mass value="0.16831092346442011"/>
    <inertia ixx="5.7e-05" iyy="0.000144" izz="0.000197" ixy="-0.0" iyz="0.0" ixz="1e-06"/>
  </inertial>
  <visual>
    <origin xyz="0 0 0" rpy="0 0 0"/>
    <geometry>
      <mesh filename="package://gripkit_cr_plus_l_dd_description/meshes/SF-ISO50-CRG200_Customer.stl" scale="0.001 0.001 0.001"/>
    </geometry>
    <material name="silver"/>
  </visual>
  <collision>
    <origin xyz="0 0 0" rpy="0 0 0"/>
    <geometry>
      <mesh filename="package://gripkit_cr_plus_l_dd_description/meshes/SF-ISO50-CRG200_Customer.stl" scale="0.001 0.001 0.001"/>
    </geometry>
  </collision>
</link>

<link name="CRG200_body">
  <inertial>
    <origin xyz="-0.046013419522296255 0.023500046460400374 0.029719376870480135" rpy="0 0 0"/>
    <mass value="1.024019455093708"/>
    <inertia ixx="0.000598" iyy="0.001224" izz="0.001229" ixy="0.0" iyz="-0.0" ixz="-0.0"/>
  </inertial>
  <visual>
    <origin xyz="-0.046 0.0235 -0.011" rpy="0 0 0"/>
    <geometry>
      <mesh filename="package://gripkit_cr_plus_l_dd_description/meshes/CRG200_body.stl" scale="0.001 0.001 0.001"/>
    </geometry>
    <material name="silver"/>
  </visual>
  <collision>
    <origin xyz="-0.046 0.0235 -0.011" rpy="0 0 0"/>
    <geometry>
      <mesh filename="package://gripkit_cr_plus_l_dd_description/meshes/CRG200_body.stl" scale="0.001 0.001 0.001"/>
    </geometry>
  </collision>
</link>

<link name="CRG200_base_jaw_1">
  <inertial>
    <origin xyz="-0.001116596745818358 -2.0816681711721685e-17 0.004896836508835337" rpy="0 0 0"/>
    <mass value="0.028974809674202275"/>
    <inertia ixx="0.0" iyy="5e-06" izz="5e-06" ixy="0.0" iyz="0.0" ixz="0.0"/>
  </inertial>
  <visual>
    <origin xyz="-0.0 0.0185 -0.0686" rpy="0 0 0"/>
    <geometry>
      <mesh filename="package://gripkit_cr_plus_l_dd_description/meshes/CRG200_base_jaw_1.stl" scale="0.001 0.001 0.001"/>
    </geometry>
    <material name="silver"/>
  </visual>
  <collision>
    <origin xyz="-0.0 0.0185 -0.0686" rpy="0 0 0"/>
    <geometry>
      <mesh filename="package://gripkit_cr_plus_l_dd_description/meshes/CRG200_base_jaw_1.stl" scale="0.001 0.001 0.001"/>
    </geometry>
  </collision>
</link>

<link name="CRG200_base_jaw_2">
  <inertial>
    <origin xyz="0.001116596745818374 1.0408340855860843e-17 0.004896836508835337" rpy="0 0 0"/>
    <mass value="0.028974809674202275"/>
    <inertia ixx="0.0" iyy="5e-06" izz="5e-06" ixy="0.0" iyz="-0.0" ixz="-0.0"/>
  </inertial>
  <visual>
    <origin xyz="-0.0 -0.0185 -0.0686" rpy="0 0 0"/>
    <geometry>
      <mesh filename="package://gripkit_cr_plus_l_dd_description/meshes/CRG200_base_jaw_2.stl" scale="0.001 0.001 0.001"/>
    </geometry>
    <material name="silver"/>
  </visual>
  <collision>
    <origin xyz="-0.0 -0.0185 -0.0686" rpy="0 0 0"/>
    <geometry>
      <mesh filename="package://gripkit_cr_plus_l_dd_description/meshes/CRG200_base_jaw_2.stl" scale="0.001 0.001 0.001"/>
    </geometry>
  </collision>
</link>

<link name="CRG200_top_cover">
  <inertial>
    <origin xyz="-2.837104009083995e-09 7.283818491274739e-09 0.0040439255937821245" rpy="0 0 0"/>
    <mass value="0.117790703444327"/>
    <inertia ixx="3.5e-05" iyy="0.000112" izz="0.000144" ixy="-0.0" iyz="-0.0" ixz="0.0"/>
  </inertial>
  <visual>
    <origin xyz="-0.0 0.0 -0.0711" rpy="0 0 0"/>
    <geometry>
      <mesh filename="package://gripkit_cr_plus_l_dd_description/meshes/CRG200_top_cover.stl" scale="0.001 0.001 0.001"/>
    </geometry>
    <material name="silver"/>
  </visual>
  <collision>
    <origin xyz="-0.0 0.0 -0.0711" rpy="0 0 0"/>
    <geometry>
      <mesh filename="package://gripkit_cr_plus_l_dd_description/meshes/CRG200_top_cover.stl" scale="0.001 0.001 0.001"/>
    </geometry>
  </collision>
</link>

<link name="ISO_4762_-_M4_x_12ISO_1">
  <inertial>
    <origin xyz="-6.938893903907228e-18 4.0060663120122797e-13 0.0022480078452116357" rpy="0 0 0"/>
    <mass value="0.002203374250243251"/>
    <inertia ixx="0.0" iyy="0.0" izz="0.0" ixy="0.0" iyz="0.0" ixz="0.0"/>
  </inertial>
  <visual>
    <origin xyz="0.046 0.0235 -0.0065" rpy="0 0 0"/>
    <geometry>
      <mesh filename="package://gripkit_cr_plus_l_dd_description/meshes/ISO_4762_-_M4_x_12ISO_1.stl" scale="0.001 0.001 0.001"/>
    </geometry>
    <material name="silver"/>
  </visual>
  <collision>
    <origin xyz="0.046 0.0235 -0.0065" rpy="0 0 0"/>
    <geometry>
      <mesh filename="package://gripkit_cr_plus_l_dd_description/meshes/ISO_4762_-_M4_x_12ISO_1.stl" scale="0.001 0.001 0.001"/>
    </geometry>
  </collision>
</link>

<link name="ISO_4762_-_M4_x_12ISO_2">
  <inertial>
    <origin xyz="6.938893903907228e-18 4.0060663120122797e-13 0.0022480078452116357" rpy="0 0 0"/>
    <mass value="0.002203374250243251"/>
    <inertia ixx="0.0" iyy="0.0" izz="0.0" ixy="-0.0" iyz="0.0" ixz="-0.0"/>
  </inertial>
  <visual>
    <origin xyz="-0.046 0.0235 -0.0065" rpy="0 0 0"/>
    <geometry>
      <mesh filename="package://gripkit_cr_plus_l_dd_description/meshes/ISO_4762_-_M4_x_12ISO_2.stl" scale="0.001 0.001 0.001"/>
    </geometry>
    <material name="silver"/>
  </visual>
  <collision>
    <origin xyz="-0.046 0.0235 -0.0065" rpy="0 0 0"/>
    <geometry>
      <mesh filename="package://gripkit_cr_plus_l_dd_description/meshes/ISO_4762_-_M4_x_12ISO_2.stl" scale="0.001 0.001 0.001"/>
    </geometry>
  </collision>
</link>

<link name="ISO_4762_-_M4_x_12ISO_3">
  <inertial>
    <origin xyz="6.938893903907228e-18 4.006101006481799e-13 0.0022480078452116357" rpy="0 0 0"/>
    <mass value="0.002203374250243251"/>
    <inertia ixx="0.0" iyy="0.0" izz="0.0" ixy="0.0" iyz="0.0" ixz="-0.0"/>
  </inertial>
  <visual>
    <origin xyz="-0.046 -0.0235 -0.0065" rpy="0 0 0"/>
    <geometry>
      <mesh filename="package://gripkit_cr_plus_l_dd_description/meshes/ISO_4762_-_M4_x_12ISO_3.stl" scale="0.001 0.001 0.001"/>
    </geometry>
    <material name="silver"/>
  </visual>
  <collision>
    <origin xyz="-0.046 -0.0235 -0.0065" rpy="0 0 0"/>
    <geometry>
      <mesh filename="package://gripkit_cr_plus_l_dd_description/meshes/ISO_4762_-_M4_x_12ISO_3.stl" scale="0.001 0.001 0.001"/>
    </geometry>
  </collision>
</link>

<link name="ISO_4762_-_M4_x_12ISO_4">
  <inertial>
    <origin xyz="-6.938893903907228e-18 4.006101006481799e-13 0.0022480078452116357" rpy="0 0 0"/>
    <mass value="0.002203374250243251"/>
    <inertia ixx="0.0" iyy="0.0" izz="0.0" ixy="0.0" iyz="0.0" ixz="0.0"/>
  </inertial>
  <visual>
    <origin xyz="0.046 -0.0235 -0.0065" rpy="0 0 0"/>
    <geometry>
      <mesh filename="package://gripkit_cr_plus_l_dd_description/meshes/ISO_4762_-_M4_x_12ISO_4.stl" scale="0.001 0.001 0.001"/>
    </geometry>
    <material name="silver"/>
  </visual>
  <collision>
    <origin xyz="0.046 -0.0235 -0.0065" rpy="0 0 0"/>
    <geometry>
      <mesh filename="package://gripkit_cr_plus_l_dd_description/meshes/ISO_4762_-_M4_x_12ISO_4.stl" scale="0.001 0.001 0.001"/>
    </geometry>
  </collision>
</link>

<link name="BE_20-030_CUSTOMER_v1_1">
  <inertial>
    <origin xyz="-0.015485870461580736 0.01020718912758817 0.00490301880176619" rpy="0 0 0"/>
    <mass value="0.07101056528211638"/>
    <inertia ixx="7e-06" iyy="8e-06" izz="1.4e-05" ixy="4e-06" iyz="-0.0" ixz="0.0"/>
  </inertial>
  <visual>
    <origin xyz="0.002 0.0185 -0.081" rpy="0 0 0"/>
    <geometry>
      <mesh filename="package://gripkit_cr_plus_l_dd_description/meshes/BE_20-030_CUSTOMER_v1_1.stl" scale="0.001 0.001 0.001"/>
    </geometry>
    <material name="silver"/>
  </visual>
  <collision>
    <origin xyz="0.002 0.0185 -0.081" rpy="0 0 0"/>
    <geometry>
      <mesh filename="package://gripkit_cr_plus_l_dd_description/meshes/BE_20-030_CUSTOMER_v1_1.stl" scale="0.001 0.001 0.001"/>
    </geometry>
  </collision>
</link>

<link name="BE_20-030_CUSTOMER_v1_2">
  <inertial>
    <origin xyz="0.015485870461580743 -0.010207189127588159 0.00490301880176619" rpy="0 0 0"/>
    <mass value="0.07101056528211638"/>
    <inertia ixx="7e-06" iyy="8e-06" izz="1.4e-05" ixy="4e-06" iyz="0.0" ixz="-0.0"/>
  </inertial>
  <visual>
    <origin xyz="-0.002 -0.0185 -0.081" rpy="0 0 0"/>
    <geometry>
      <mesh filename="package://gripkit_cr_plus_l_dd_description/meshes/BE_20-030_CUSTOMER_v1_2.stl" scale="0.001 0.001 0.001"/>
    </geometry>
    <material name="silver"/>
  </visual>
  <collision>
    <origin xyz="-0.002 -0.0185 -0.081" rpy="0 0 0"/>
    <geometry>
      <mesh filename="package://gripkit_cr_plus_l_dd_description/meshes/BE_20-030_CUSTOMER_v1_2.stl" scale="0.001 0.001 0.001"/>
    </geometry>
  </collision>
</link>

<link name="FE_20-050_CUSTOMER_v1_1">
  <inertial>
    <origin xyz="-0.024908407665588207 -2.6135871897188265e-17 6.768003808813039e-05" rpy="0 0 0"/>
    <mass value="0.11001397809346045"/>
    <inertia ixx="8e-06" iyy="4.5e-05" izz="4.4e-05" ixy="0.0" iyz="0.0" ixz="-7e-06"/>
  </inertial>
  <visual>
    <origin xyz="0.027 -0.0 -0.091" rpy="0 0 0"/>
    <geometry>
      <mesh filename="package://gripkit_cr_plus_l_dd_description/meshes/FE_20-050_CUSTOMER_v1_1.stl" scale="0.001 0.001 0.001"/>
    </geometry>
    <material name="silver"/>
  </visual>
  <collision>
    <origin xyz="0.027 -0.0 -0.091" rpy="0 0 0"/>
    <geometry>
      <mesh filename="package://gripkit_cr_plus_l_dd_description/meshes/FE_20-050_CUSTOMER_v1_1.stl" scale="0.001 0.001 0.001"/>
    </geometry>
  </collision>
</link>

<link name="FE_20-050_CUSTOMER_v1_2">
  <inertial>
    <origin xyz="0.02490840766558833 8.435305924828848e-18 6.768003808813039e-05" rpy="0 0 0"/>
    <mass value="0.11001397809346045"/>
    <inertia ixx="8e-06" iyy="4.5e-05" izz="4.4e-05" ixy="0.0" iyz="0.0" ixz="7e-06"/>
  </inertial>
  <visual>
    <origin xyz="-0.027 -0.0 -0.091" rpy="0 0 0"/>
    <geometry>
      <mesh filename="package://gripkit_cr_plus_l_dd_description/meshes/FE_20-050_CUSTOMER_v1_2.stl" scale="0.001 0.001 0.001"/>
    </geometry>
    <material name="silver"/>
  </visual>
  <collision>
    <origin xyz="-0.027 -0.0 -0.091" rpy="0 0 0"/>
    <geometry>
      <mesh filename="package://gripkit_cr_plus_l_dd_description/meshes/FE_20-050_CUSTOMER_v1_2.stl" scale="0.001 0.001 0.001"/>
    </geometry>
  </collision>
</link>

<link name="AC_20-025_CUSTOMER_v1_1">
  <inertial>
    <origin xyz="-0.0019437600342788464 -1.9817227657202033e-17 0.014328388306272574" rpy="0 0 0"/>
    <mass value="0.07018824497649055"/>
    <inertia ixx="9e-06" iyy="9e-06" izz="4e-06" ixy="-0.0" iyz="-0.0" ixz="1e-06"/>
  </inertial>
  <visual>
    <origin xyz="0.077 0.0 -0.091" rpy="0 0 0"/>
    <geometry>
      <mesh filename="package://gripkit_cr_plus_l_dd_description/meshes/AC_20-025_CUSTOMER_v1_1.stl" scale="0.001 0.001 0.001"/>
    </geometry>
    <material name="silver"/>
  </visual>
  <collision>
    <origin xyz="0.077 0.0 -0.091" rpy="0 0 0"/>
    <geometry>
      <mesh filename="package://gripkit_cr_plus_l_dd_description/meshes/AC_20-025_CUSTOMER_v1_1.stl" scale="0.001 0.001 0.001"/>
    </geometry>
  </collision>
</link>

<link name="AC_20-025_CUSTOMER_v1_2">
  <inertial>
    <origin xyz="0.0019437600342767924 5.427537459056158e-18 0.014328388306272866" rpy="0 0 0"/>
    <mass value="0.07018824497649055"/>
    <inertia ixx="9e-06" iyy="9e-06" izz="4e-06" ixy="-0.0" iyz="0.0" ixz="-1e-06"/>
  </inertial>
  <visual>
    <origin xyz="-0.077 -0.0 -0.091" rpy="0 0 0"/>
    <geometry>
      <mesh filename="package://gripkit_cr_plus_l_dd_description/meshes/AC_20-025_CUSTOMER_v1_2.stl" scale="0.001 0.001 0.001"/>
    </geometry>
    <material name="silver"/>
  </visual>
  <collision>
    <origin xyz="-0.077 -0.0 -0.091" rpy="0 0 0"/>
    <geometry>
      <mesh filename="package://gripkit_cr_plus_l_dd_description/meshes/AC_20-025_CUSTOMER_v1_2.stl" scale="0.001 0.001 0.001"/>
    </geometry>
  </collision>
</link>

<link name="FT_20-UNI_CUSTOMER_v1_1">
  <inertial>
    <origin xyz="0.009779007136435189 -2.235646858940691e-14 6.046606342505201e-05" rpy="0 0 0"/>
    <mass value="0.05314853137521012"/>
    <inertia ixx="3e-06" iyy="3e-06" izz="3e-06" ixy="-0.0" iyz="0.0" ixz="-0.0"/>
  </inertial>
  <visual>
    <origin xyz="0.077 0.0 -0.116" rpy="0 0 0"/>
    <geometry>
      <mesh filename="package://gripkit_cr_plus_l_dd_description/meshes/FT_20-UNI_CUSTOMER_v1_1.stl" scale="0.001 0.001 0.001"/>
    </geometry>
    <material name="silver"/>
  </visual>
  <collision>
    <origin xyz="0.077 0.0 -0.116" rpy="0 0 0"/>
    <geometry>
      <mesh filename="package://gripkit_cr_plus_l_dd_description/meshes/FT_20-UNI_CUSTOMER_v1_1.stl" scale="0.001 0.001 0.001"/>
    </geometry>
  </collision>
</link>

<link name="FT_20-UNI_CUSTOMER_v1_2">
  <inertial>
    <origin xyz="-0.009779007136438894 2.2335780717162037e-14 6.046606342341443e-05" rpy="0 0 0"/>
    <mass value="0.05314853137521012"/>
    <inertia ixx="3e-06" iyy="3e-06" izz="3e-06" ixy="-0.0" iyz="-0.0" ixz="0.0"/>
  </inertial>
  <visual>
    <origin xyz="-0.077 -0.0 -0.116" rpy="0 0 0"/>
    <geometry>
      <mesh filename="package://gripkit_cr_plus_l_dd_description/meshes/FT_20-UNI_CUSTOMER_v1_2.stl" scale="0.001 0.001 0.001"/>
    </geometry>
    <material name="silver"/>
  </visual>
  <collision>
    <origin xyz="-0.077 -0.0 -0.116" rpy="0 0 0"/>
    <geometry>
      <mesh filename="package://gripkit_cr_plus_l_dd_description/meshes/FT_20-UNI_CUSTOMER_v1_2.stl" scale="0.001 0.001 0.001"/>
    </geometry>
  </collision>
</link>

<joint name="Rigid10" type="fixed">
  <origin xyz="0.046 -0.0235 0.011" rpy="0 0 0"/>
  <parent link="SF-ISO50-CRG200_Customer"/>
  <child link="CRG200_body"/>
</joint>

<joint name="Slider01" type="prismatic">
  <origin xyz="-0.046 0.005 0.0576" rpy="0 0 0"/>
  <parent link="CRG200_body"/>
  <child link="CRG200_base_jaw_1"/>
  <axis xyz="1.0 0.0 0.0"/>
  <limit upper="0.021" lower="-0.021" effort="${max_effort}" velocity="${max_velocity}"/>
</joint>

<joint name="Slider02" type="prismatic">
  <origin xyz="-0.046 0.042 0.0576" rpy="0 0 0"/>
  <parent link="CRG200_body"/>
  <child link="CRG200_base_jaw_2"/>
  <axis xyz="1.0 0.0 0.0"/>
  <limit upper="0.021" lower="-0.021" effort="${max_effort}" velocity="${max_velocity}"/>
</joint>

<joint name="Rigid11" type="fixed">
  <origin xyz="-0.046 0.0235 0.0601" rpy="0 0 0"/>
  <parent link="CRG200_body"/>
  <child link="CRG200_top_cover"/>
</joint>

<joint name="Rigid12" type="fixed">
  <origin xyz="-0.046 -0.0235 0.0065" rpy="0 0 0"/>
  <parent link="SF-ISO50-CRG200_Customer"/>
  <child link="ISO_4762_-_M4_x_12ISO_1"/>
</joint>

<joint name="Rigid13" type="fixed">
  <origin xyz="0.046 -0.0235 0.0065" rpy="0 0 0"/>
  <parent link="SF-ISO50-CRG200_Customer"/>
  <child link="ISO_4762_-_M4_x_12ISO_2"/>
</joint>

<joint name="Rigid14" type="fixed">
  <origin xyz="0.046 0.0235 0.0065" rpy="0 0 0"/>
  <parent link="SF-ISO50-CRG200_Customer"/>
  <child link="ISO_4762_-_M4_x_12ISO_3"/>
</joint>

<joint name="Rigid15" type="fixed">
  <origin xyz="-0.046 0.0235 0.0065" rpy="0 0 0"/>
  <parent link="SF-ISO50-CRG200_Customer"/>
  <child link="ISO_4762_-_M4_x_12ISO_4"/>
</joint>

<joint name="Rigid16" type="fixed">
  <origin xyz="-0.002 0.0 0.0124" rpy="0 0 0"/>
  <parent link="CRG200_base_jaw_1"/>
  <child link="BE_20-030_CUSTOMER_v1_1"/>
</joint>

<joint name="Rigid17" type="fixed">
  <origin xyz="0.002 0.0 0.0124" rpy="0 0 0"/>
  <parent link="CRG200_base_jaw_2"/>
  <child link="BE_20-030_CUSTOMER_v1_2"/>
</joint>

<joint name="Rigid18" type="fixed">
  <origin xyz="-0.025 0.0185 0.01" rpy="0 0 0"/>
  <parent link="BE_20-030_CUSTOMER_v1_1"/>
  <child link="FE_20-050_CUSTOMER_v1_1"/>
</joint>

<joint name="Rigid19" type="fixed">
  <origin xyz="0.025 -0.0185 0.01" rpy="0 0 0"/>
  <parent link="BE_20-030_CUSTOMER_v1_2"/>
  <child link="FE_20-050_CUSTOMER_v1_2"/>
</joint>

<joint name="Rigid20" type="fixed">
  <origin xyz="-0.05 -0.0 0.0" rpy="0 0 0"/>
  <parent link="FE_20-050_CUSTOMER_v1_1"/>
  <child link="AC_20-025_CUSTOMER_v1_1"/>
</joint>

<joint name="Rigid21" type="fixed">
  <origin xyz="0.05 0.0 0.0" rpy="0 0 0"/>
  <parent link="FE_20-050_CUSTOMER_v1_2"/>
  <child link="AC_20-025_CUSTOMER_v1_2"/>
</joint>

<joint name="Rigid22" type="fixed">
  <origin xyz="0.0 0.0 0.025" rpy="0 0 0"/>
  <parent link="AC_20-025_CUSTOMER_v1_1"/>
  <child link="FT_20-UNI_CUSTOMER_v1_1"/>
</joint>

<joint name="Rigid23" type="fixed">
  <origin xyz="0.0 0.0 0.025" rpy="0 0 0"/>
  <parent link="AC_20-025_CUSTOMER_v1_2"/>
  <child link="FT_20-UNI_CUSTOMER_v1_2"/>
</joint>

</robot>
