<?xml version="1.0" ?>
<robot name="kmr_iiwa" xmlns:xacro="http://www.ros.org/wiki/xacro">

<xacro:include filename="$(find kmr_iiwa_description)/urdf/materials.xacro" />
<xacro:include filename="$(find kmr_iiwa_description)/urdf/kmr_iiwa.trans" />
<xacro:include filename="$(find kmr_iiwa_description)/urdf/kmr_iiwa.gazebo" />
<link name="base_footprint">
</link>
<link name="base_link">
  <inertial>
    <origin xyz="0.8106390374956872 1.0657568144166023 0.5062997486659317" rpy="0 0 0"/>
    <mass value="3266.3922537057438"/>
    <inertia ixx="226.744522" iyy="400.752195" izz="384.998869" ixy="-2.223757" iyz="-1.110451" ixz="10.295288"/>
  </inertial>
  <visual>
    <origin xyz="0 0 0" rpy="0 0 0"/>
    <geometry>
      <mesh filename="package://kmr_iiwa_description/meshes/base_link.stl" scale="0.001 0.001 0.001"/>
    </geometry>
    <material name="silver"/>
  </visual>
  <collision>
    <origin xyz="0 0 0" rpy="0 0 0"/>
    <geometry>
      <mesh filename="package://kmr_iiwa_description/meshes/base_link.stl" scale="0.001 0.001 0.001"/>
    </geometry>
  </collision>
</link>

<link name="screw_1_1">
  <inertial>
    <origin xyz="-0.0010380640298013333 1.4573301299614094e-05 6.386517521494994e-06" rpy="0 0 0"/>
    <mass value="0.002693161929654313"/>
    <inertia ixx="0.0" iyy="0.0" izz="0.0" ixy="-0.0" iyz="0.0" ixz="-0.0"/>
  </inertial>
  <visual>
    <origin xyz="-1.138705 -0.879925 -2.090781" rpy="0 0 0"/>
    <geometry>
      <mesh filename="package://kmr_iiwa_description/meshes/screw_1_1.stl" scale="0.001 0.001 0.001"/>
    </geometry>
    <material name="silver"/>
  </visual>
  <collision>
    <origin xyz="-1.138705 -0.879925 -2.090781" rpy="0 0 0"/>
    <geometry>
      <mesh filename="package://kmr_iiwa_description/meshes/screw_1_1.stl" scale="0.001 0.001 0.001"/>
    </geometry>
  </collision>
</link>

<link name="screw_2_1">
  <inertial>
    <origin xyz="8.226225265417497e-07 0.0010376006209378286 -1.6471234598469664e-05" rpy="0 0 0"/>
    <mass value="0.0026932173030154564"/>
    <inertia ixx="0.0" iyy="0.0" izz="0.0" ixy="0.0" iyz="-0.0" ixz="0.0"/>
  </inertial>
  <visual>
    <origin xyz="-1.189005 -0.930225 -2.090781" rpy="0 0 0"/>
    <geometry>
      <mesh filename="package://kmr_iiwa_description/meshes/screw_2_1.stl" scale="0.001 0.001 0.001"/>
    </geometry>
    <material name="silver"/>
  </visual>
  <collision>
    <origin xyz="-1.189005 -0.930225 -2.090781" rpy="0 0 0"/>
    <geometry>
      <mesh filename="package://kmr_iiwa_description/meshes/screw_2_1.stl" scale="0.001 0.001 0.001"/>
    </geometry>
  </collision>
</link>

<link name="screw_3_1">
  <inertial>
    <origin xyz="0.001037536514163051 3.8899127385860766e-06 1.5601911371732058e-05" rpy="0 0 0"/>
    <mass value="0.002693745664184645"/>
    <inertia ixx="0.0" iyy="0.0" izz="0.0" ixy="0.0" iyz="0.0" ixz="0.0"/>
  </inertial>
  <visual>
    <origin xyz="-1.239305 -0.879925 -2.090781" rpy="0 0 0"/>
    <geometry>
      <mesh filename="package://kmr_iiwa_description/meshes/screw_3_1.stl" scale="0.001 0.001 0.001"/>
    </geometry>
    <material name="silver"/>
  </visual>
  <collision>
    <origin xyz="-1.239305 -0.879925 -2.090781" rpy="0 0 0"/>
    <geometry>
      <mesh filename="package://kmr_iiwa_description/meshes/screw_3_1.stl" scale="0.001 0.001 0.001"/>
    </geometry>
  </collision>
</link>

<link name="screw_4_1">
  <inertial>
    <origin xyz="-1.612639555825801e-05 -0.0010381612803640472 -1.6489430536559269e-06" rpy="0 0 0"/>
    <mass value="0.0026933743563882172"/>
    <inertia ixx="0.0" iyy="0.0" izz="0.0" ixy="0.0" iyz="-0.0" ixz="0.0"/>
  </inertial>
  <visual>
    <origin xyz="-1.189005 -0.829625 -2.090781" rpy="0 0 0"/>
    <geometry>
      <mesh filename="package://kmr_iiwa_description/meshes/screw_4_1.stl" scale="0.001 0.001 0.001"/>
    </geometry>
    <material name="silver"/>
  </visual>
  <collision>
    <origin xyz="-1.189005 -0.829625 -2.090781" rpy="0 0 0"/>
    <geometry>
      <mesh filename="package://kmr_iiwa_description/meshes/screw_4_1.stl" scale="0.001 0.001 0.001"/>
    </geometry>
  </collision>
</link>

<link name="screw_5_1">
  <inertial>
    <origin xyz="-0.0007445569604616065 -0.0007216575671826764 -2.1726751775474895e-07" rpy="0 0 0"/>
    <mass value="0.002693701452940877"/>
    <inertia ixx="0.0" iyy="0.0" izz="0.0" ixy="-0.0" iyz="-0.0" ixz="0.0"/>
  </inertial>
  <visual>
    <origin xyz="-1.153439 -0.844352 -2.085851" rpy="0 0 0"/>
    <geometry>
      <mesh filename="package://kmr_iiwa_description/meshes/screw_5_1.stl" scale="0.001 0.001 0.001"/>
    </geometry>
    <material name="silver"/>
  </visual>
  <collision>
    <origin xyz="-1.153439 -0.844352 -2.085851" rpy="0 0 0"/>
    <geometry>
      <mesh filename="package://kmr_iiwa_description/meshes/screw_5_1.stl" scale="0.001 0.001 0.001"/>
    </geometry>
  </collision>
</link>

<link name="screw_6_1">
  <inertial>
    <origin xyz="0.0007226592739872917 0.0007454180602156635 2.33742872390863e-06" rpy="0 0 0"/>
    <mass value="0.0026933936118932553"/>
    <inertia ixx="0.0" iyy="0.0" izz="0.0" ixy="-0.0" iyz="0.0" ixz="-0.0"/>
  </inertial>
  <visual>
    <origin xyz="-1.224574 -0.915487 -2.085851" rpy="0 0 0"/>
    <geometry>
      <mesh filename="package://kmr_iiwa_description/meshes/screw_6_1.stl" scale="0.001 0.001 0.001"/>
    </geometry>
    <material name="silver"/>
  </visual>
  <collision>
    <origin xyz="-1.224574 -0.915487 -2.085851" rpy="0 0 0"/>
    <geometry>
      <mesh filename="package://kmr_iiwa_description/meshes/screw_6_1.stl" scale="0.001 0.001 0.001"/>
    </geometry>
  </collision>
</link>

<link name="cover_1">
  <inertial>
    <origin xyz="0.013259466659639951 1.790353112429699e-07 -0.22267494931922704" rpy="0 0 0"/>
    <mass value="7.737707490873716"/>
    <inertia ixx="0.059177" iyy="0.024648" izz="0.03712" ixy="0.0" iyz="-0.0" ixz="0.001342"/>
  </inertial>
  <visual>
    <origin xyz="-1.366207 -1.06392 -0.784151" rpy="0 0 0"/>
    <geometry>
      <mesh filename="package://kmr_iiwa_description/meshes/cover_1.stl" scale="0.001 0.001 0.001"/>
    </geometry>
    <material name="silver"/>
  </visual>
  <collision>
    <origin xyz="-1.366207 -1.06392 -0.784151" rpy="0 0 0"/>
    <geometry>
      <mesh filename="package://kmr_iiwa_description/meshes/cover_1.stl" scale="0.001 0.001 0.001"/>
    </geometry>
  </collision>
</link>

<link name="link_1_1">
  <inertial>
    <origin xyz="-0.03473370179647017 -3.5562173505976347e-07 0.12351602455445043" rpy="0 0 0"/>
    <mass value="21.213888253656222"/>
    <inertia ixx="0.127957" iyy="0.13413" izz="0.047327" ixy="-0.0" iyz="-0.0" ixz="0.023881"/>
  </inertial>
  <visual>
    <origin xyz="-1.189207 -0.87992 -0.989851" rpy="0 0 0"/>
    <geometry>
      <mesh filename="package://kmr_iiwa_description/meshes/link_1_1.stl" scale="0.001 0.001 0.001"/>
    </geometry>
    <material name="silver"/>
  </visual>
  <collision>
    <origin xyz="-1.189207 -0.87992 -0.989851" rpy="0 0 0"/>
    <geometry>
      <mesh filename="package://kmr_iiwa_description/meshes/link_1_1.stl" scale="0.001 0.001 0.001"/>
    </geometry>
  </collision>
</link>

<link name="link_2_1">
  <inertial>
    <origin xyz="0.04491493029193894 -3.134336603594079e-07 0.06732543874287211" rpy="0 0 0"/>
    <mass value="21.397098230942653"/>
    <inertia ixx="0.127529" iyy="0.133838" izz="0.047851" ixy="0.0" iyz="-0.0" ixz="0.02227"/>
  </inertial>
  <visual>
    <origin xyz="-1.178707 -0.87992 -1.182851" rpy="0 0 0"/>
    <geometry>
      <mesh filename="package://kmr_iiwa_description/meshes/link_2_1.stl" scale="0.001 0.001 0.001"/>
    </geometry>
    <material name="silver"/>
  </visual>
  <collision>
    <origin xyz="-1.178707 -0.87992 -1.182851" rpy="0 0 0"/>
    <geometry>
      <mesh filename="package://kmr_iiwa_description/meshes/link_2_1.stl" scale="0.001 0.001 0.001"/>
    </geometry>
  </collision>
</link>

<link name="link_3_1">
  <inertial>
    <origin xyz="0.029563494603055185 -2.715439469946901e-07 0.13650340399479655" rpy="0 0 0"/>
    <mass value="24.923668408341197"/>
    <inertia ixx="0.186887" iyy="0.196866" izz="0.059721" ixy="0.0" iyz="0.0" ixz="-0.038259"/>
  </inertial>
  <visual>
    <origin xyz="-1.189207 -0.87992 -1.357351" rpy="0 0 0"/>
    <geometry>
      <mesh filename="package://kmr_iiwa_description/meshes/link_3_1.stl" scale="0.001 0.001 0.001"/>
    </geometry>
    <material name="silver"/>
  </visual>
  <collision>
    <origin xyz="-1.189207 -0.87992 -1.357351" rpy="0 0 0"/>
    <geometry>
      <mesh filename="package://kmr_iiwa_description/meshes/link_3_1.stl" scale="0.001 0.001 0.001"/>
    </geometry>
  </collision>
</link>

<link name="link_4_1">
  <inertial>
    <origin xyz="-0.044915931670632236 -2.0462086236516797e-07 0.06732526675638217" rpy="0 0 0"/>
    <mass value="21.397084006482324"/>
    <inertia ixx="0.127521" iyy="0.133811" izz="0.047832" ixy="-0.0" iyz="0.0" ixz="-0.022267"/>
  </inertial>
  <visual>
    <origin xyz="-1.199707 -0.87992 -1.582851" rpy="0 0 0"/>
    <geometry>
      <mesh filename="package://kmr_iiwa_description/meshes/link_4_1.stl" scale="0.001 0.001 0.001"/>
    </geometry>
    <material name="silver"/>
  </visual>
  <collision>
    <origin xyz="-1.199707 -0.87992 -1.582851" rpy="0 0 0"/>
    <geometry>
      <mesh filename="package://kmr_iiwa_description/meshes/link_4_1.stl" scale="0.001 0.001 0.001"/>
    </geometry>
  </collision>
</link>

<link name="link_5_1">
  <inertial>
    <origin xyz="-0.02138678187235521 -2.506369201071834e-07 0.08546840131270783" rpy="0 0 0"/>
    <mass value="13.296685148643036"/>
    <inertia ixx="0.068318" iyy="0.079123" izz="0.035085" ixy="0.0" iyz="-0.0" ixz="0.024261"/>
  </inertial>
  <visual>
    <origin xyz="-1.189207 -0.87992 -1.757351" rpy="0 0 0"/>
    <geometry>
      <mesh filename="package://kmr_iiwa_description/meshes/link_5_1.stl" scale="0.001 0.001 0.001"/>
    </geometry>
    <material name="silver"/>
  </visual>
  <collision>
    <origin xyz="-1.189207 -0.87992 -1.757351" rpy="0 0 0"/>
    <geometry>
      <mesh filename="package://kmr_iiwa_description/meshes/link_5_1.stl" scale="0.001 0.001 0.001"/>
    </geometry>
  </collision>
</link>

<link name="link_6_1">
  <inertial>
    <origin xyz="0.07098669332173979 1.8928840606058372e-08 0.00211548105867454" rpy="0 0 0"/>
    <mass value="14.421198781272748"/>
    <inertia ixx="0.038461" iyy="0.040001" izz="0.027817" ixy="-0.0" iyz="-0.0" ixz="0.00196"/>
  </inertial>
  <visual>
    <origin xyz="-1.118507 -0.87992 -1.982851" rpy="0 0 0"/>
    <geometry>
      <mesh filename="package://kmr_iiwa_description/meshes/link_6_1.stl" scale="0.001 0.001 0.001"/>
    </geometry>
    <material name="silver"/>
  </visual>
  <collision>
    <origin xyz="-1.118507 -0.87992 -1.982851" rpy="0 0 0"/>
    <geometry>
      <mesh filename="package://kmr_iiwa_description/meshes/link_6_1.stl" scale="0.001 0.001 0.001"/>
    </geometry>
  </collision>
</link>

<link name="flange_1">
  <inertial>
    <origin xyz="-1.7426738052606083e-07 -4.9185258471640125e-06 0.009981717476648111" rpy="0 0 0"/>
    <mass value="2.1030620192288976"/>
    <inertia ixx="0.001534" iyy="0.001534" izz="0.00251" ixy="1.5e-05" iyz="0.0" ixz="-0.0"/>
  </inertial>
  <visual>
    <origin xyz="-1.189007 -0.87992 -2.073751" rpy="0 0 0"/>
    <geometry>
      <mesh filename="package://kmr_iiwa_description/meshes/flange_1.stl" scale="0.001 0.001 0.001"/>
    </geometry>
    <material name="silver"/>
  </visual>
  <collision>
    <origin xyz="-1.189007 -0.87992 -2.073751" rpy="0 0 0"/>
    <geometry>
      <mesh filename="package://kmr_iiwa_description/meshes/flange_1.stl" scale="0.001 0.001 0.001"/>
    </geometry>
  </collision>
</link>

<link name="link_0_1">
  <inertial>
    <origin xyz="-2.371965932557174e-07 0.0128321715690628 0.06810412602451121" rpy="0 0 0"/>
    <mass value="30.321448900186642"/>
    <inertia ixx="0.139451" iyy="0.111656" izz="0.133146" ixy="0.0" iyz="-0.004809" ixz="-0.0"/>
  </inertial>
  <visual>
    <origin xyz="-1.189207 -0.87992 -0.844351" rpy="0 0 0"/>
    <geometry>
      <mesh filename="package://kmr_iiwa_description/meshes/link_0_1.stl" scale="0.001 0.001 0.001"/>
    </geometry>
    <material name="silver"/>
  </visual>
  <collision>
    <origin xyz="-1.189207 -0.87992 -0.844351" rpy="0 0 0"/>
    <geometry>
      <mesh filename="package://kmr_iiwa_description/meshes/link_0_1.stl" scale="0.001 0.001 0.001"/>
    </geometry>
  </collision>
</link>

<joint name="base_footprint_joint" type="fixed">
  <origin xyz="0 0 0" rpy="0 0 0"/>
  <parent link="base_footprint"/>
  <child link="base_link"/>
</joint>

<joint name="Rigid18" type="fixed">
  <origin xyz="-0.050302 5e-06 0.01703" rpy="0 0 0"/>
  <parent link="flange_1"/>
  <child link="screw_1_1"/>
</joint>

<joint name="Rigid19" type="fixed">
  <origin xyz="-2e-06 0.050305 0.01703" rpy="0 0 0"/>
  <parent link="flange_1"/>
  <child link="screw_2_1"/>
</joint>

<joint name="Rigid20" type="fixed">
  <origin xyz="0.050298 5e-06 0.01703" rpy="0 0 0"/>
  <parent link="flange_1"/>
  <child link="screw_3_1"/>
</joint>

<joint name="Rigid21" type="fixed">
  <origin xyz="-2e-06 -0.050295 0.01703" rpy="0 0 0"/>
  <parent link="flange_1"/>
  <child link="screw_4_1"/>
</joint>

<joint name="Rigid22" type="fixed">
  <origin xyz="-0.035568 -0.035568 0.0121" rpy="0 0 0"/>
  <parent link="flange_1"/>
  <child link="screw_5_1"/>
</joint>

<joint name="Rigid23" type="fixed">
  <origin xyz="0.035567 0.035567 0.0121" rpy="0 0 0"/>
  <parent link="flange_1"/>
  <child link="screw_6_1"/>
</joint>

<joint name="Rigid24" type="fixed">
  <origin xyz="1.366207 1.06392 0.784151" rpy="0 0 0"/>
  <parent link="base_link"/>
  <child link="cover_1"/>
</joint>

<joint name="Rev25" type="revolute">
  <origin xyz="0.0 0.0 0.1455" rpy="0 0 0"/>
  <parent link="link_0_1"/>
  <child link="link_1_1"/>
  <axis xyz="0.0 -0.0 1.0"/>
  <limit upper="2.96706" lower="-2.96706" effort="100" velocity="100"/>
</joint>

<joint name="Rev26" type="revolute">
  <origin xyz="-0.0105 0.0 0.193" rpy="0 0 0"/>
  <parent link="link_1_1"/>
  <child link="link_2_1"/>
  <axis xyz="1.0 0.0 0.0"/>
  <limit upper="2.094395" lower="-2.094395" effort="100" velocity="100"/>
</joint>

<joint name="Rev27" type="revolute">
  <origin xyz="0.0105 0.0 0.1745" rpy="0 0 0"/>
  <parent link="link_2_1"/>
  <child link="link_3_1"/>
  <axis xyz="0.0 -0.0 1.0"/>
  <limit upper="2.96706" lower="-2.96706" effort="100" velocity="100"/>
</joint>

<joint name="Rev28" type="revolute">
  <origin xyz="0.0105 0.0 0.2255" rpy="0 0 0"/>
  <parent link="link_3_1"/>
  <child link="link_4_1"/>
  <axis xyz="-1.0 -0.0 -0.0"/>
  <limit upper="2.094395" lower="-2.094395" effort="100" velocity="100"/>
</joint>

<joint name="Rev29" type="revolute">
  <origin xyz="-0.0105 0.0 0.1745" rpy="0 0 0"/>
  <parent link="link_4_1"/>
  <child link="link_5_1"/>
  <axis xyz="0.0 -0.0 1.0"/>
  <limit upper="2.96706" lower="-2.96706" effort="100" velocity="100"/>
</joint>

<joint name="Rev30" type="revolute">
  <origin xyz="-0.0707 0.0 0.2255" rpy="0 0 0"/>
  <parent link="link_5_1"/>
  <child link="link_6_1"/>
  <axis xyz="1.0 0.0 0.0"/>
  <limit upper="2.094395" lower="-2.094395" effort="100" velocity="100"/>
</joint>

<joint name="Rev31" type="revolute">
  <origin xyz="0.0705 0.0 0.0909" rpy="0 0 0"/>
  <parent link="link_6_1"/>
  <child link="flange_1"/>
  <axis xyz="0.0 -0.0 1.0"/>
  <limit upper="3.054326" lower="-3.054326" effort="100" velocity="100"/>
</joint>

<joint name="Rigid33" type="fixed">
  <origin xyz="1.189207 0.87992 0.844351" rpy="0 0 0"/>
  <parent link="base_link"/>
  <child link="link_0_1"/>
</joint>

</robot>
