<?xml version="1.0" ?>
<robot name="iiwa7" xmlns:xacro="http://www.ros.org/wiki/xacro">

<xacro:include filename="$(find iiwa7_description)/urdf/materials.xacro" />
<xacro:include filename="$(find iiwa7_description)/urdf/iiwa7.trans" />
<xacro:include filename="$(find iiwa7_description)/urdf/iiwa7.gazebo" />
<link name="base_footprint">
</link>
<link name="base_link">
  <inertial>
    <origin xyz="-0.012832431040764161 -4.5637556731516346e-08 0.07010426148644754" rpy="0 0 0"/>
    <mass value="30.321448900186642"/>
    <inertia ixx="0.111656" iyy="0.139451" izz="0.133146" ixy="-0.0" iyz="-0.0" ixz="0.004809"/>
  </inertial>
  <visual>
    <origin xyz="0 0 0" rpy="0 0 0"/>
    <geometry>
      <mesh filename="package://iiwa7_description/meshes/base_link.stl" scale="0.001 0.001 0.001"/>
    </geometry>
    <material name="silver"/>
  </visual>
  <collision>
    <origin xyz="0 0 0" rpy="0 0 0"/>
    <geometry>
      <mesh filename="package://iiwa7_description/meshes/base_link.stl" scale="0.001 0.001 0.001"/>
    </geometry>
  </collision>
</link>

<link name="screw_1_1">
  <inertial>
    <origin xyz="-1.4832773006889655e-05 -0.0010378724707667056 6.521979453832927e-06" rpy="0 0 0"/>
    <mass value="0.002693161929654313"/>
    <inertia ixx="0.0" iyy="0.0" izz="0.0" ixy="0.0" iyz="-0.0" ixz="-0.0"/>
  </inertial>
  <visual>
    <origin xyz="5e-06 0.050502 -1.24843" rpy="0 0 0"/>
    <geometry>
      <mesh filename="package://iiwa7_description/meshes/screw_1_1.stl" scale="0.001 0.001 0.001"/>
    </geometry>
    <material name="silver"/>
  </visual>
  <collision>
    <origin xyz="5e-06 0.050502 -1.24843" rpy="0 0 0"/>
    <geometry>
      <mesh filename="package://iiwa7_description/meshes/screw_1_1.stl" scale="0.001 0.001 0.001"/>
    </geometry>
  </collision>
</link>

<link name="screw_2_1">
  <inertial>
    <origin xyz="-0.0010378600926400153 1.0141815646168306e-06 -1.6335772665687642e-05" rpy="0 0 0"/>
    <mass value="0.0026932173030154564"/>
    <inertia ixx="0.0" iyy="0.0" izz="0.0" ixy="-0.0" iyz="0.0" ixz="0.0"/>
  </inertial>
  <visual>
    <origin xyz="0.050305 0.000202 -1.24843" rpy="0 0 0"/>
    <geometry>
      <mesh filename="package://iiwa7_description/meshes/screw_2_1.stl" scale="0.001 0.001 0.001"/>
    </geometry>
    <material name="silver"/>
  </visual>
  <collision>
    <origin xyz="0.050305 0.000202 -1.24843" rpy="0 0 0"/>
    <geometry>
      <mesh filename="package://iiwa7_description/meshes/screw_2_1.stl" scale="0.001 0.001 0.001"/>
    </geometry>
  </collision>
</link>

<link name="screw_3_1">
  <inertial>
    <origin xyz="-4.149384437101288e-06 0.0010377280731967073 1.5737373303847946e-05" rpy="0 0 0"/>
    <mass value="0.002693745664184645"/>
    <inertia ixx="0.0" iyy="0.0" izz="0.0" ixy="-0.0" iyz="0.0" ixz="-0.0"/>
  </inertial>
  <visual>
    <origin xyz="5e-06 -0.050098 -1.24843" rpy="0 0 0"/>
    <geometry>
      <mesh filename="package://iiwa7_description/meshes/screw_3_1.stl" scale="0.001 0.001 0.001"/>
    </geometry>
    <material name="silver"/>
  </visual>
  <collision>
    <origin xyz="5e-06 -0.050098 -1.24843" rpy="0 0 0"/>
    <geometry>
      <mesh filename="package://iiwa7_description/meshes/screw_3_1.stl" scale="0.001 0.001 0.001"/>
    </geometry>
  </collision>
</link>

<link name="screw_4_1">
  <inertial>
    <origin xyz="0.0010379018086611527 -1.593483652835768e-05 -1.5134811208739052e-06" rpy="0 0 0"/>
    <mass value="0.0026933743563882172"/>
    <inertia ixx="0.0" iyy="0.0" izz="0.0" ixy="-0.0" iyz="0.0" ixz="0.0"/>
  </inertial>
  <visual>
    <origin xyz="-0.050295 0.000202 -1.24843" rpy="0 0 0"/>
    <geometry>
      <mesh filename="package://iiwa7_description/meshes/screw_4_1.stl" scale="0.001 0.001 0.001"/>
    </geometry>
    <material name="silver"/>
  </visual>
  <collision>
    <origin xyz="-0.050295 0.000202 -1.24843" rpy="0 0 0"/>
    <geometry>
      <mesh filename="package://iiwa7_description/meshes/screw_4_1.stl" scale="0.001 0.001 0.001"/>
    </geometry>
  </collision>
</link>

<link name="screw_5_1">
  <inertial>
    <origin xyz="0.0007223980954759596 -0.0007453654014303521 -8.180558541681648e-08" rpy="0 0 0"/>
    <mass value="0.002693701452940877"/>
    <inertia ixx="0.0" iyy="0.0" izz="0.0" ixy="0.0" iyz="0.0" ixz="0.0"/>
  </inertial>
  <visual>
    <origin xyz="-0.035567 0.035767 -1.2435" rpy="0 0 0"/>
    <geometry>
      <mesh filename="package://iiwa7_description/meshes/screw_5_1.stl" scale="0.001 0.001 0.001"/>
    </geometry>
    <material name="silver"/>
  </visual>
  <collision>
    <origin xyz="-0.035567 0.035767 -1.2435" rpy="0 0 0"/>
    <geometry>
      <mesh filename="package://iiwa7_description/meshes/screw_5_1.stl" scale="0.001 0.001 0.001"/>
    </geometry>
  </collision>
</link>

<link name="screw_6_1">
  <inertial>
    <origin xyz="-0.0007456775319143946 0.0007228508330246464 2.4728906569126963e-06" rpy="0 0 0"/>
    <mass value="0.0026933936118932553"/>
    <inertia ixx="0.0" iyy="0.0" izz="0.0" ixy="0.0" iyz="-0.0" ixz="-0.0"/>
  </inertial>
  <visual>
    <origin xyz="0.035567 -0.035367 -1.2435" rpy="0 0 0"/>
    <geometry>
      <mesh filename="package://iiwa7_description/meshes/screw_6_1.stl" scale="0.001 0.001 0.001"/>
    </geometry>
    <material name="silver"/>
  </visual>
  <collision>
    <origin xyz="0.035567 -0.035367 -1.2435" rpy="0 0 0"/>
    <geometry>
      <mesh filename="package://iiwa7_description/meshes/screw_6_1.stl" scale="0.001 0.001 0.001"/>
    </geometry>
  </collision>
</link>

<link name="link_1_1">
  <inertial>
    <origin xyz="9.615003024343416e-08 -0.03473351023743466 0.12351616001638635" rpy="0 0 0"/>
    <mass value="21.213888253656222"/>
    <inertia ixx="0.13413" iyy="0.127957" izz="0.047327" ixy="0.0" iyz="0.023881" ixz="0.0"/>
  </inertial>
  <visual>
    <origin xyz="-0.0 0.0 -0.1475" rpy="0 0 0"/>
    <geometry>
      <mesh filename="package://iiwa7_description/meshes/link_1_1.stl" scale="0.001 0.001 0.001"/>
    </geometry>
    <material name="silver"/>
  </visual>
  <collision>
    <origin xyz="-0.0 0.0 -0.1475" rpy="0 0 0"/>
    <geometry>
      <mesh filename="package://iiwa7_description/meshes/link_1_1.stl" scale="0.001 0.001 0.001"/>
    </geometry>
  </collision>
</link>

<link name="link_2_1">
  <inertial>
    <origin xyz="5.3961961621630917e-08 0.04491512185097363 0.06732557420480756" rpy="0 0 0"/>
    <mass value="21.397098230942653"/>
    <inertia ixx="0.133838" iyy="0.127529" izz="0.047851" ixy="-0.0" iyz="0.02227" ixz="0.0"/>
  </inertial>
  <visual>
    <origin xyz="0.0 0.0105 -0.3405" rpy="0 0 0"/>
    <geometry>
      <mesh filename="package://iiwa7_description/meshes/link_2_1.stl" scale="0.001 0.001 0.001"/>
    </geometry>
    <material name="silver"/>
  </visual>
  <collision>
    <origin xyz="0.0 0.0105 -0.3405" rpy="0 0 0"/>
    <geometry>
      <mesh filename="package://iiwa7_description/meshes/link_2_1.stl" scale="0.001 0.001 0.001"/>
    </geometry>
  </collision>
</link>

<link name="link_3_1">
  <inertial>
    <origin xyz="1.207224751269193e-08 0.029563686162089268 0.13650353945673122" rpy="0 0 0"/>
    <mass value="24.923668408341197"/>
    <inertia ixx="0.196866" iyy="0.186887" izz="0.059721" ixy="-0.0" iyz="-0.038259" ixz="-0.0"/>
  </inertial>
  <visual>
    <origin xyz="0.0 0.0 -0.515" rpy="0 0 0"/>
    <geometry>
      <mesh filename="package://iiwa7_description/meshes/link_3_1.stl" scale="0.001 0.001 0.001"/>
    </geometry>
    <material name="silver"/>
  </visual>
  <collision>
    <origin xyz="0.0 0.0 -0.515" rpy="0 0 0"/>
    <geometry>
      <mesh filename="package://iiwa7_description/meshes/link_3_1.stl" scale="0.001 0.001 0.001"/>
    </geometry>
  </collision>
</link>

<link name="link_4_1">
  <inertial>
    <origin xyz="-5.485084286249875e-08 -0.044915740111597394 0.06732540221831629" rpy="0 0 0"/>
    <mass value="21.397084006482324"/>
    <inertia ixx="0.133811" iyy="0.127521" izz="0.047832" ixy="0.0" iyz="-0.022267" ixz="-0.0"/>
  </inertial>
  <visual>
    <origin xyz="0.0 -0.0105 -0.7405" rpy="0 0 0"/>
    <geometry>
      <mesh filename="package://iiwa7_description/meshes/link_4_1.stl" scale="0.001 0.001 0.001"/>
    </geometry>
    <material name="silver"/>
  </visual>
  <collision>
    <origin xyz="0.0 -0.0105 -0.7405" rpy="0 0 0"/>
    <geometry>
      <mesh filename="package://iiwa7_description/meshes/link_4_1.stl" scale="0.001 0.001 0.001"/>
    </geometry>
  </collision>
</link>

<link name="link_5_1">
  <inertial>
    <origin xyz="-8.834784191987874e-09 -0.02138659031332106 0.08546853677464128" rpy="0 0 0"/>
    <mass value="13.296685148643036"/>
    <inertia ixx="0.079123" iyy="0.068318" izz="0.035085" ixy="-0.0" iyz="0.024261" ixz="0.0"/>
  </inertial>
  <visual>
    <origin xyz="0.0 0.0 -0.915" rpy="0 0 0"/>
    <geometry>
      <mesh filename="package://iiwa7_description/meshes/link_5_1.stl" scale="0.001 0.001 0.001"/>
    </geometry>
    <material name="silver"/>
  </visual>
  <collision>
    <origin xyz="0.0 0.0 -0.915" rpy="0 0 0"/>
    <geometry>
      <mesh filename="package://iiwa7_description/meshes/link_5_1.stl" scale="0.001 0.001 0.001"/>
    </geometry>
  </collision>
</link>

<link name="link_6_1">
  <inertial>
    <origin xyz="-2.784005425940048e-07 0.07098688488077398 0.002115616520607766" rpy="0 0 0"/>
    <mass value="14.421198781272748"/>
    <inertia ixx="0.040001" iyy="0.038461" izz="0.027817" ixy="0.0" iyz="0.00196" ixz="0.0"/>
  </inertial>
  <visual>
    <origin xyz="0.0 0.0707 -1.1405" rpy="0 0 0"/>
    <geometry>
      <mesh filename="package://iiwa7_description/meshes/link_6_1.stl" scale="0.001 0.001 0.001"/>
    </geometry>
    <material name="silver"/>
  </visual>
  <collision>
    <origin xyz="0.0 0.0707 -1.1405" rpy="0 0 0"/>
    <geometry>
      <mesh filename="package://iiwa7_description/meshes/link_6_1.stl" scale="0.001 0.001 0.001"/>
    </geometry>
  </collision>
</link>

<link name="flange_1">
  <inertial>
    <origin xyz="4.659054144329294e-06 1.7291653306211654e-08 0.009981852938580671" rpy="0 0 0"/>
    <mass value="2.1030620192288976"/>
    <inertia ixx="0.001534" iyy="0.001534" izz="0.00251" ixy="-1.5e-05" iyz="-0.0" ixz="-0.0"/>
  </inertial>
  <visual>
    <origin xyz="0.0 0.0002 -1.2314" rpy="0 0 0"/>
    <geometry>
      <mesh filename="package://iiwa7_description/meshes/flange_1.stl" scale="0.001 0.001 0.001"/>
    </geometry>
    <material name="silver"/>
  </visual>
  <collision>
    <origin xyz="0.0 0.0002 -1.2314" rpy="0 0 0"/>
    <geometry>
      <mesh filename="package://iiwa7_description/meshes/flange_1.stl" scale="0.001 0.001 0.001"/>
    </geometry>
  </collision>
</link>

<joint name="base_footprint_joint" type="fixed">
  <origin xyz="0 0 0" rpy="0 0 0"/>
  <parent link="base_footprint"/>
  <child link="base_link"/>
</joint>

<joint name="Rigid18" type="fixed">
  <origin xyz="-5e-06 -0.050302 0.01703" rpy="0 0 0"/>
  <parent link="flange_1"/>
  <child link="screw_1_1"/>
</joint>

<joint name="Rigid19" type="fixed">
  <origin xyz="-0.050305 -2e-06 0.01703" rpy="0 0 0"/>
  <parent link="flange_1"/>
  <child link="screw_2_1"/>
</joint>

<joint name="Rigid20" type="fixed">
  <origin xyz="-5e-06 0.050298 0.01703" rpy="0 0 0"/>
  <parent link="flange_1"/>
  <child link="screw_3_1"/>
</joint>

<joint name="Rigid21" type="fixed">
  <origin xyz="0.050295 -2e-06 0.01703" rpy="0 0 0"/>
  <parent link="flange_1"/>
  <child link="screw_4_1"/>
</joint>

<joint name="Rigid22" type="fixed">
  <origin xyz="0.035567 -0.035567 0.0121" rpy="0 0 0"/>
  <parent link="flange_1"/>
  <child link="screw_5_1"/>
</joint>

<joint name="Rigid23" type="fixed">
  <origin xyz="-0.035567 0.035567 0.0121" rpy="0 0 0"/>
  <parent link="flange_1"/>
  <child link="screw_6_1"/>
</joint>

<joint name="Rev44" type="revolute">
  <origin xyz="0.0 0.0 0.1475" rpy="0 0 0"/>
  <parent link="base_link"/>
  <child link="link_1_1"/>
  <axis xyz="0.0 0.0 1.0"/>
  <limit upper="2.96706" lower="-2.96706" effort="100" velocity="100"/>
</joint>

<joint name="Rev45" type="revolute">
  <origin xyz="-0.0 -0.0105 0.193" rpy="0 0 0"/>
  <parent link="link_1_1"/>
  <child link="link_2_1"/>
  <axis xyz="0.0 1.0 0.0"/>
  <limit upper="2.094395" lower="-2.094395" effort="100" velocity="100"/>
</joint>

<joint name="Rev46" type="revolute">
  <origin xyz="0.0 0.0105 0.1745" rpy="0 0 0"/>
  <parent link="link_2_1"/>
  <child link="link_3_1"/>
  <axis xyz="0.0 0.0 1.0"/>
  <limit upper="2.96706" lower="-2.96706" effort="100" velocity="100"/>
</joint>

<joint name="Rev47" type="revolute">
  <origin xyz="0.0 0.0105 0.2255" rpy="0 0 0"/>
  <parent link="link_3_1"/>
  <child link="link_4_1"/>
  <axis xyz="0.0 -1.0 0.0"/>
  <limit upper="2.094395" lower="-2.094395" effort="100" velocity="100"/>
</joint>

<joint name="Rev48" type="revolute">
  <origin xyz="0.0 -0.0105 0.1745" rpy="0 0 0"/>
  <parent link="link_4_1"/>
  <child link="link_5_1"/>
  <axis xyz="0.0 0.0 1.0"/>
  <limit upper="2.96706" lower="-2.96706" effort="100" velocity="100"/>
</joint>

<joint name="Rev49" type="revolute">
  <origin xyz="0.0 -0.0707 0.2255" rpy="0 0 0"/>
  <parent link="link_5_1"/>
  <child link="link_6_1"/>
  <axis xyz="0.0 1.0 0.0"/>
  <limit upper="2.094395" lower="-2.094395" effort="100" velocity="100"/>
</joint>

<joint name="Rev50" type="revolute">
  <origin xyz="0.0 0.0705 0.0909" rpy="0 0 0"/>
  <parent link="link_6_1"/>
  <child link="flange_1"/>
  <axis xyz="0.0 0.0 1.0"/>
  <limit upper="3.054326" lower="-3.054326" effort="100" velocity="100"/>
</joint>

</robot>
