<?xml version="1.0" ?>
<robot name="iiwa7" xmlns:xacro="http://www.ros.org/wiki/xacro">

<xacro:include filename="$(find iiwa7_description)/urdf/iiwa7.trans" />
<xacro:include filename="$(find iiwa7_description)/urdf/iiwa7.gazebo" />

<link name="world">
</link>
<link name="base_footprint">
</link>
<link name="link_0">
  <inertial>
    <origin xyz="-0.012832431040764161 -4.5637556731516346e-08 0.07010426148644754" rpy="0 0 0"/>
    <mass value="5"/>
    <inertia ixx="0.05" ixy="0" ixz="0" iyy="0.06" iyz="0" izz="0.03"/>
  </inertial>
  <visual>
    <origin xyz="0 0 0" rpy="0 0 0"/>
    <geometry>
      <mesh filename="package://iiwa7_description/meshes/link_0.stl" scale="0.001 0.001 0.001"/>
    </geometry>
    <material name="silver"/>
  </visual>
  <collision>
    <origin xyz="0 0 0" rpy="0 0 0"/>
    <geometry>
      <mesh filename="package://iiwa7_description/meshes/link_0.stl" scale="0.001 0.001 0.001"/>
    </geometry>
  </collision>
</link>

<link name="screw_1">
  <inertial>
    <origin xyz="0.00010532202107516823 0.0010327802160219474 6.521979454054971e-06" rpy="0 0 0"/>
    <mass value="0.002693161929654313"/>
    <inertia ixx="0.0" iyy="0.0" izz="0.0" ixy="0.0" iyz="0.0" ixz="0.0"/>
  </inertial>
  <visual>
    <origin xyz="-0.004389 -0.04991 -1.24843" rpy="0 0 0"/>
    <geometry>
      <mesh filename="package://iiwa7_description/meshes/screw_1.stl" scale="0.001 0.001 0.001"/>
    </geometry>
    <material name="silver"/>
  </visual>
  <collision>
    <origin xyz="-0.004389 -0.04991 -1.24843" rpy="0 0 0"/>
    <geometry>
      <mesh filename="package://iiwa7_description/meshes/screw_1.stl" scale="0.001 0.001 0.001"/>
    </geometry>
  </collision>
</link>

<link name="screw_2">
  <inertial>
    <origin xyz="0.0010335709288897404 -9.08430390645712e-05 -1.6335772665687642e-05" rpy="0 0 0"/>
    <mass value="0.0026932173030154564"/>
    <inertia ixx="0.0" iyy="0.0" izz="0.0" ixy="0.0" iyz="-0.0" ixz="-0.0"/>
  </inertial>
  <visual>
    <origin xyz="-0.050114 0.004583 -1.24843" rpy="0 0 0"/>
    <geometry>
      <mesh filename="package://iiwa7_description/meshes/screw_2.stl" scale="0.001 0.001 0.001"/>
    </geometry>
    <material name="silver"/>
  </visual>
  <collision>
    <origin xyz="-0.050114 0.004583 -1.24843" rpy="0 0 0"/>
    <geometry>
      <mesh filename="package://iiwa7_description/meshes/screw_2.stl" scale="0.001 0.001 0.001"/>
    </geometry>
  </collision>
</link>

<link name="screw_3">
  <inertial>
    <origin xyz="-8.608894144667995e-05 -0.001034177550594477 1.573737330406999e-05" rpy="0 0 0"/>
    <mass value="0.002693745664184645"/>
    <inertia ixx="0.0" iyy="0.0" izz="0.0" ixy="-0.0" iyz="-0.0" ixz="0.0"/>
  </inertial>
  <visual>
    <origin xyz="0.004379 0.050307 -1.24843" rpy="0 0 0"/>
    <geometry>
      <mesh filename="package://iiwa7_description/meshes/screw_3.stl" scale="0.001 0.001 0.001"/>
    </geometry>
    <material name="silver"/>
  </visual>
  <collision>
    <origin xyz="0.004379 0.050307 -1.24843" rpy="0 0 0"/>
    <geometry>
      <mesh filename="package://iiwa7_description/meshes/screw_3.stl" scale="0.001 0.001 0.001"/>
    </geometry>
  </collision>
</link>

<link name="screw_4">
  <inertial>
    <origin xyz="-0.0010320014954562015 0.00010682377358710391 -1.5134811206518606e-06" rpy="0 0 0"/>
    <mass value="0.0026933743563882172"/>
    <inertia ixx="0.0" iyy="0.0" izz="0.0" ixy="-0.0" iyz="-0.0" ixz="-0.0"/>
  </inertial>
  <visual>
    <origin xyz="0.050104 -0.004185 -1.24843" rpy="0 0 0"/>
    <geometry>
      <mesh filename="package://iiwa7_description/meshes/screw_4.stl" scale="0.001 0.001 0.001"/>
    </geometry>
    <material name="silver"/>
  </visual>
  <collision>
    <origin xyz="0.050104 -0.004185 -1.24843" rpy="0 0 0"/>
    <geometry>
      <mesh filename="package://iiwa7_description/meshes/screw_4.stl" scale="0.001 0.001 0.001"/>
    </geometry>
  </collision>
</link>

<link name="screw_5">
  <inertial>
    <origin xyz="-0.0006544748021702906 0.0008050153329516724 -8.180558541681648e-08" rpy="0 0 0"/>
    <mass value="0.002693701452940877"/>
    <inertia ixx="0.0" iyy="0.0" izz="0.0" ixy="0.0" iyz="-0.0" ixz="-0.0"/>
  </inertial>
  <visual>
    <origin xyz="0.032332 -0.038332 -1.2435" rpy="0 0 0"/>
    <geometry>
      <mesh filename="package://iiwa7_description/meshes/screw_5.stl" scale="0.001 0.001 0.001"/>
    </geometry>
    <material name="silver"/>
  </visual>
  <collision>
    <origin xyz="0.032332 -0.038332 -1.2435" rpy="0 0 0"/>
    <geometry>
      <mesh filename="package://iiwa7_description/meshes/screw_5.stl" scale="0.001 0.001 0.001"/>
    </geometry>
  </collision>
</link>

<link name="screw_6">
  <inertial>
    <origin xyz="0.0006796279272519301 -0.0007846153758497079 2.472890657134741e-06" rpy="0 0 0"/>
    <mass value="0.0026933936118932553"/>
    <inertia ixx="0.0" iyy="0.0" izz="0.0" ixy="0.0" iyz="0.0" ixz="0.0"/>
  </inertial>
  <visual>
    <origin xyz="-0.032332 0.038732 -1.2435" rpy="0 0 0"/>
    <geometry>
      <mesh filename="package://iiwa7_description/meshes/screw_6.stl" scale="0.001 0.001 0.001"/>
    </geometry>
    <material name="silver"/>
  </visual>
  <collision>
    <origin xyz="-0.032332 0.038732 -1.2435" rpy="0 0 0"/>
    <geometry>
      <mesh filename="package://iiwa7_description/meshes/screw_6.stl" scale="0.001 0.001 0.001"/>
    </geometry>
  </collision>
</link>

<link name="link_1">
  <inertial>
    <origin xyz="9.615003024343416e-08 -0.03473351023743466 0.12351616001638635" rpy="0 0 0"/>
    <mass value="3.4525"/>
    <inertia ixx="0.02183" ixy="0" ixz="0" iyy="0.007703" iyz="-0.003887" izz="0.02083"/>
  </inertial>
  <visual>
    <origin xyz="-0.0 0.0 -0.1475" rpy="0 0 0"/>
    <geometry>
      <mesh filename="package://iiwa7_description/meshes/link_1.stl" scale="0.001 0.001 0.001"/>
    </geometry>
    <material name="silver"/>
  </visual>
  <collision>
    <origin xyz="-0.0 0.0 -0.1475" rpy="0 0 0"/>
    <geometry>
      <mesh filename="package://iiwa7_description/meshes/link_1.stl" scale="0.001 0.001 0.001"/>
    </geometry>
  </collision>
</link>

<link name="link_2">
  <inertial>
    <origin xyz="5.3961961621630917e-08 0.04491512185097363 0.06732557420480756" rpy="0 0 0"/>
    <mass value="3.4821"/>
    <inertia ixx="0.02076"  ixy="0"  ixz="-0.003626" iyy="0.02179" iyz="0" izz="0.00779"/>
  </inertial>
  <visual>
    <origin xyz="0.0 0.0105 -0.3405" rpy="0 0 0"/>
    <geometry>
      <mesh filename="package://iiwa7_description/meshes/link_2.stl" scale="0.001 0.001 0.001"/>
    </geometry>
    <material name="silver"/>
  </visual>
  <collision>
    <origin xyz="0.0 0.0105 -0.3405" rpy="0 0 0"/>
    <geometry>
      <mesh filename="package://iiwa7_description/meshes/link_2.stl" scale="0.001 0.001 0.001"/>
    </geometry>
  </collision>
</link>

<link name="link_3">
  <inertial>
    <origin xyz="1.207224751269193e-08 0.029563686162089268 0.13650353945673122" rpy="0 0 0"/>
    <mass value="4.05623"/>
    <inertia ixx="0.03204"  ixy="0"  ixz="0" iyy="0.00972" iyz="0.006227" izz="0.03042"/>
  </inertial>
  <visual>
    <origin xyz="0.0 0.0 -0.515" rpy="0 0 0"/>
    <geometry>
      <mesh filename="package://iiwa7_description/meshes/link_3.stl" scale="0.001 0.001 0.001"/>
    </geometry>
    <material name="silver"/>
  </visual>
  <collision>
    <origin xyz="0.0 0.0 -0.515" rpy="0 0 0"/>
    <geometry>
      <mesh filename="package://iiwa7_description/meshes/link_3.stl" scale="0.001 0.001 0.001"/>
    </geometry>
  </collision>
</link>

<link name="link_4">
  <inertial>
    <origin xyz="-5.485084286249875e-08 -0.044915740111597394 0.06732540221831629" rpy="0 0 0"/>
    <mass value="3.4822"/>
    <inertia ixx="0.02178"  ixy="0"  ixz="0" iyy="0.02075" iyz="-0.003625" izz="0.007785"/>
  </inertial>
  <visual>
    <origin xyz="0.0 -0.0105 -0.7405" rpy="0 0 0"/>
    <geometry>
      <mesh filename="package://iiwa7_description/meshes/link_4.stl" scale="0.001 0.001 0.001"/>
    </geometry>
    <material name="silver"/>
  </visual>
  <collision>
    <origin xyz="0.0 -0.0105 -0.7405" rpy="0 0 0"/>
    <geometry>
      <mesh filename="package://iiwa7_description/meshes/link_4.stl" scale="0.001 0.001 0.001"/>
    </geometry>
  </collision>
</link>

<link name="link_5">
  <inertial>
    <origin xyz="-8.834784191987874e-09 -0.02138659031332106 0.08546853677464128" rpy="0 0 0"/>
    <mass value="2.1633"/>
    <inertia ixx="0.01287"  ixy="0"  ixz="0" iyy="0.005708" iyz="-0.003946" izz="0.01112"/>
  </inertial>
  <visual>
    <origin xyz="0.0 0.0 -0.915" rpy="0 0 0"/>
    <geometry>
      <mesh filename="package://iiwa7_description/meshes/link_5.stl" scale="0.001 0.001 0.001"/>
    </geometry>
    <material name="silver"/>
  </visual>
  <collision>
    <origin xyz="0.0 0.0 -0.915" rpy="0 0 0"/>
    <geometry>
      <mesh filename="package://iiwa7_description/meshes/link_5.stl" scale="0.001 0.001 0.001"/>
    </geometry>
  </collision>
</link>

<link name="link_6">
  <inertial>
    <origin xyz="-2.784005425984457e-07 0.07098688488077398 0.002115616520607766" rpy="0 0 0"/>
    <mass value="2.3466"/>
    <inertia ixx="0.006509"  ixy="0"  ixz="0" iyy="0.006259" iyz="0.00031891" izz="0.004527"/>
  </inertial>
  <visual>
    <origin xyz="0.0 0.0707 -1.1405" rpy="0 0 0"/>
    <geometry>
      <mesh filename="package://iiwa7_description/meshes/link_6.stl" scale="0.001 0.001 0.001"/>
    </geometry>
    <material name="silver"/>
  </visual>
  <collision>
    <origin xyz="0.0 0.0707 -1.1405" rpy="0 0 0"/>
    <geometry>
      <mesh filename="package://iiwa7_description/meshes/link_6.stl" scale="0.001 0.001 0.001"/>
    </geometry>
  </collision>
</link>

<link name="flange">
  <inertial>
    <origin xyz="-4.642832106049604e-06 3.8883747105610965e-07 0.009981852938580671" rpy="0 0 0"/>
    <mass value="3.129"/>
    <inertia ixx="0.01464"  ixy="0.0005912"  ixz="0" iyy="0.01465" iyz="0" izz="0.002872"/>
  </inertial>
  <visual>
    <origin xyz="0.0 0.0002 -1.2314" rpy="0 0 0"/>
    <geometry>
      <mesh filename="package://iiwa7_description/meshes/flange.stl" scale="0.001 0.001 0.001"/>
    </geometry>
    <material name="silver"/>
  </visual>
  <collision>
    <origin xyz="0.0 0.0002 -1.2314" rpy="0 0 0"/>
    <geometry>
      <mesh filename="package://iiwa7_description/meshes/flange.stl" scale="0.001 0.001 0.001"/>
    </geometry>
  </collision>
</link>

<joint name="world_joint" type="fixed">
  <origin xyz="0 0 0" rpy="0 0 0"/>
  <parent link="world"/>
  <child link="base_footprint"/>
</joint>

<joint name="base_footprint_joint" type="fixed">
  <origin xyz="0 0 0" rpy="0 0 0"/>
  <parent link="base_footprint"/>
  <child link="link_0"/>
</joint>

<joint name="Rigid01" type="fixed">
  <origin xyz="0.004389 0.05011 0.01703" rpy="0 0 0"/>
  <parent link="flange"/>
  <child link="screw_1"/>
</joint>

<joint name="Rigid02" type="fixed">
  <origin xyz="0.050114 -0.004383 0.01703" rpy="0 0 0"/>
  <parent link="flange"/>
  <child link="screw_2"/>
</joint>

<joint name="Rigid03" type="fixed">
  <origin xyz="-0.004379 -0.050107 0.01703" rpy="0 0 0"/>
  <parent link="flange"/>
  <child link="screw_3"/>
</joint>

<joint name="Rigid04" type="fixed">
  <origin xyz="-0.050104 0.004385 0.01703" rpy="0 0 0"/>
  <parent link="flange"/>
  <child link="screw_4"/>
</joint>

<joint name="Rigid05" type="fixed">
  <origin xyz="-0.032332 0.038532 0.0121" rpy="0 0 0"/>
  <parent link="flange"/>
  <child link="screw_5"/>
</joint>

<joint name="Rigid06" type="fixed">
  <origin xyz="0.032332 -0.038532 0.0121" rpy="0 0 0"/>
  <parent link="flange"/>
  <child link="screw_6"/>
</joint>

<joint name="Rev01" type="revolute">
  <origin xyz="0.0 0.0 0.1475" rpy="0 0 0"/>
  <parent link="link_0"/>
  <child link="link_1"/>
  <axis xyz="0.0 0.0 1.0"/>
  <limit upper="2.96706" lower="-2.96706" effort="100" velocity="100"/>
</joint>

<joint name="Rev02" type="revolute">
  <origin xyz="-0.0 -0.0105 0.193" rpy="0 0 0"/>
  <parent link="link_1"/>
  <child link="link_2"/>
  <axis xyz="0.0 1.0 0.0"/>
  <limit upper="2.094395" lower="-2.094395" effort="100" velocity="100"/>
</joint>

<joint name="Rev03" type="revolute">
  <origin xyz="0.0 0.0105 0.1745" rpy="0 0 0"/>
  <parent link="link_2"/>
  <child link="link_3"/>
  <axis xyz="0.0 0.0 1.0"/>
  <limit upper="2.96706" lower="-2.96706" effort="100" velocity="100"/>
</joint>

<joint name="Rev04" type="revolute">
  <origin xyz="0.0 0.0105 0.2255" rpy="0 0 0"/>
  <parent link="link_3"/>
  <child link="link_4"/>
  <axis xyz="0.0 -1.0 0.0"/>
  <limit upper="2.094395" lower="-2.094395" effort="100" velocity="100"/>
</joint>

<joint name="Rev05" type="revolute">
  <origin xyz="0.0 -0.0105 0.1745" rpy="0 0 0"/>
  <parent link="link_4"/>
  <child link="link_5"/>
  <axis xyz="0.0 0.0 1.0"/>
  <limit upper="2.96706" lower="-2.96706" effort="100" velocity="100"/>
</joint>

<joint name="Rev06" type="revolute">
  <origin xyz="0.0 -0.0707 0.2255" rpy="0 0 0"/>
  <parent link="link_5"/>
  <child link="link_6"/>
  <axis xyz="0.0 1.0 0.0"/>
  <limit upper="2.094395" lower="-2.094395" effort="100" velocity="100"/>
</joint>

<joint name="Rev07" type="revolute">
  <origin xyz="0.0 0.0705 0.0909" rpy="0 0 0"/>
  <parent link="link_6"/>
  <child link="flange"/>
  <axis xyz="0.0 0.0 1.0"/>
  <limit upper="3.054326" lower="-3.054326" effort="100" velocity="100"/>
</joint>

</robot>
