<?xml version="1.0" ?>
<robot name="iiwa_gripkit_cr_plus_l_cc" xmlns:xacro="http://www.ros.org/wiki/xacro">

<xacro:include filename="$(find iiwa_gripkit_cr_plus_l_cc_description)/urdf/materials.xacro" />
<xacro:include filename="$(find iiwa_gripkit_cr_plus_l_cc_description)/urdf/iiwa_gripkit_cr_plus_l_cc.trans" />
<xacro:include filename="$(find iiwa_gripkit_cr_plus_l_cc_description)/urdf/iiwa_gripkit_cr_plus_l_cc.gazebo" />
<link name="base_footprint">
</link>
<link name="base_link">
  <inertial>
    <origin xyz="-0.012832431040764161 -4.5637556731516346e-08 0.07010426148644754" rpy="0 0 0"/>
    <mass value="30.321448900186642"/>
    <inertia ixx="0.111656" iyy="0.139451" izz="0.133146" ixy="-0.0" iyz="-0.0" ixz="0.004809"/>
  </inertial>
  <visual>
    <origin xyz="0 0 0" rpy="0 0 0"/>
    <geometry>
      <mesh filename="package://iiwa_gripkit_cr_plus_l_cc_description/meshes/base_link.stl" scale="0.001 0.001 0.001"/>
    </geometry>
    <material name="silver"/>
  </visual>
  <collision>
    <origin xyz="0 0 0" rpy="0 0 0"/>
    <geometry>
      <mesh filename="package://iiwa_gripkit_cr_plus_l_cc_description/meshes/base_link.stl" scale="0.001 0.001 0.001"/>
    </geometry>
  </collision>
</link>

<link name="screw_1_1">
  <inertial>
    <origin xyz="-1.4832773006895218e-05 -0.0010378724707667056 6.521979453832927e-06" rpy="0 0 0"/>
    <mass value="0.002693161929654313"/>
    <inertia ixx="0.0" iyy="0.0" izz="0.0" ixy="0.0" iyz="-0.0" ixz="-0.0"/>
  </inertial>
  <visual>
    <origin xyz="5e-06 0.050502 -1.24843" rpy="0 0 0"/>
    <geometry>
      <mesh filename="package://iiwa_gripkit_cr_plus_l_cc_description/meshes/screw_1_1.stl" scale="0.001 0.001 0.001"/>
    </geometry>
    <material name="silver"/>
  </visual>
  <collision>
    <origin xyz="5e-06 0.050502 -1.24843" rpy="0 0 0"/>
    <geometry>
      <mesh filename="package://iiwa_gripkit_cr_plus_l_cc_description/meshes/screw_1_1.stl" scale="0.001 0.001 0.001"/>
    </geometry>
  </collision>
</link>

<link name="screw_2_1">
  <inertial>
    <origin xyz="-0.0010378600926400222 1.0141815646177521e-06 -1.6335772665687642e-05" rpy="0 0 0"/>
    <mass value="0.0026932173030154573"/>
    <inertia ixx="0.0" iyy="0.0" izz="0.0" ixy="-0.0" iyz="0.0" ixz="0.0"/>
  </inertial>
  <visual>
    <origin xyz="0.050305 0.000202 -1.24843" rpy="0 0 0"/>
    <geometry>
      <mesh filename="package://iiwa_gripkit_cr_plus_l_cc_description/meshes/screw_2_1.stl" scale="0.001 0.001 0.001"/>
    </geometry>
    <material name="silver"/>
  </visual>
  <collision>
    <origin xyz="0.050305 0.000202 -1.24843" rpy="0 0 0"/>
    <geometry>
      <mesh filename="package://iiwa_gripkit_cr_plus_l_cc_description/meshes/screw_2_1.stl" scale="0.001 0.001 0.001"/>
    </geometry>
  </collision>
</link>

<link name="screw_3_1">
  <inertial>
    <origin xyz="-4.149384437106851e-06 0.0010377280731967073 1.5737373303847946e-05" rpy="0 0 0"/>
    <mass value="0.002693745664184645"/>
    <inertia ixx="0.0" iyy="0.0" izz="0.0" ixy="-0.0" iyz="0.0" ixz="-0.0"/>
  </inertial>
  <visual>
    <origin xyz="5e-06 -0.050098 -1.24843" rpy="0 0 0"/>
    <geometry>
      <mesh filename="package://iiwa_gripkit_cr_plus_l_cc_description/meshes/screw_3_1.stl" scale="0.001 0.001 0.001"/>
    </geometry>
    <material name="silver"/>
  </visual>
  <collision>
    <origin xyz="5e-06 -0.050098 -1.24843" rpy="0 0 0"/>
    <geometry>
      <mesh filename="package://iiwa_gripkit_cr_plus_l_cc_description/meshes/screw_3_1.stl" scale="0.001 0.001 0.001"/>
    </geometry>
  </collision>
</link>

<link name="screw_4_1">
  <inertial>
    <origin xyz="0.0010379018086611527 -1.593483652835681e-05 -1.5134811208739052e-06" rpy="0 0 0"/>
    <mass value="0.0026933743563882172"/>
    <inertia ixx="0.0" iyy="0.0" izz="0.0" ixy="-0.0" iyz="0.0" ixz="0.0"/>
  </inertial>
  <visual>
    <origin xyz="-0.050295 0.000202 -1.24843" rpy="0 0 0"/>
    <geometry>
      <mesh filename="package://iiwa_gripkit_cr_plus_l_cc_description/meshes/screw_4_1.stl" scale="0.001 0.001 0.001"/>
    </geometry>
    <material name="silver"/>
  </visual>
  <collision>
    <origin xyz="-0.050295 0.000202 -1.24843" rpy="0 0 0"/>
    <geometry>
      <mesh filename="package://iiwa_gripkit_cr_plus_l_cc_description/meshes/screw_4_1.stl" scale="0.001 0.001 0.001"/>
    </geometry>
  </collision>
</link>

<link name="screw_5_1">
  <inertial>
    <origin xyz="0.0007223980954759526 -0.0007453654014303521 -8.18055858609057e-08" rpy="0 0 0"/>
    <mass value="0.002693701452940877"/>
    <inertia ixx="0.0" iyy="0.0" izz="0.0" ixy="0.0" iyz="0.0" ixz="0.0"/>
  </inertial>
  <visual>
    <origin xyz="-0.035567 0.035767 -1.2435" rpy="0 0 0"/>
    <geometry>
      <mesh filename="package://iiwa_gripkit_cr_plus_l_cc_description/meshes/screw_5_1.stl" scale="0.001 0.001 0.001"/>
    </geometry>
    <material name="silver"/>
  </visual>
  <collision>
    <origin xyz="-0.035567 0.035767 -1.2435" rpy="0 0 0"/>
    <geometry>
      <mesh filename="package://iiwa_gripkit_cr_plus_l_cc_description/meshes/screw_5_1.stl" scale="0.001 0.001 0.001"/>
    </geometry>
  </collision>
</link>

<link name="screw_6_1">
  <inertial>
    <origin xyz="-0.0007456775319143946 0.0007228508330246464 2.4728906569126963e-06" rpy="0 0 0"/>
    <mass value="0.0026933936118932553"/>
    <inertia ixx="0.0" iyy="0.0" izz="0.0" ixy="0.0" iyz="-0.0" ixz="-0.0"/>
  </inertial>
  <visual>
    <origin xyz="0.035567 -0.035367 -1.2435" rpy="0 0 0"/>
    <geometry>
      <mesh filename="package://iiwa_gripkit_cr_plus_l_cc_description/meshes/screw_6_1.stl" scale="0.001 0.001 0.001"/>
    </geometry>
    <material name="silver"/>
  </visual>
  <collision>
    <origin xyz="0.035567 -0.035367 -1.2435" rpy="0 0 0"/>
    <geometry>
      <mesh filename="package://iiwa_gripkit_cr_plus_l_cc_description/meshes/screw_6_1.stl" scale="0.001 0.001 0.001"/>
    </geometry>
  </collision>
</link>

<link name="SF-ISO50-CRG200_Customer_1">
  <inertial>
    <origin xyz="-0.0008393872453184791 0.02500013268462229 0.005627799924905474" rpy="0 0 0"/>
    <mass value="0.16831092346442011"/>
    <inertia ixx="5.7e-05" iyy="0.000144" izz="0.000197" ixy="-0.0" iyz="0.0" ixz="1e-06"/>
  </inertial>
  <visual>
    <origin xyz="0.0 0.0252 -1.2665" rpy="0 0 0"/>
    <geometry>
      <mesh filename="package://iiwa_gripkit_cr_plus_l_cc_description/meshes/SF-ISO50-CRG200_Customer_1.stl" scale="0.001 0.001 0.001"/>
    </geometry>
    <material name="silver"/>
  </visual>
  <collision>
    <origin xyz="0.0 0.0252 -1.2665" rpy="0 0 0"/>
    <geometry>
      <mesh filename="package://iiwa_gripkit_cr_plus_l_cc_description/meshes/SF-ISO50-CRG200_Customer_1.stl" scale="0.001 0.001 0.001"/>
    </geometry>
  </collision>
</link>

<link name="CRG200_body_1">
  <inertial>
    <origin xyz="-0.04601341952229749 0.023500046460400287 0.029719376870479985" rpy="0 0 0"/>
    <mass value="1.024019455093708"/>
    <inertia ixx="0.000598" iyy="0.001224" izz="0.001229" ixy="0.0" iyz="-0.0" ixz="-0.0"/>
  </inertial>
  <visual>
    <origin xyz="-0.046 0.0237 -1.2775" rpy="0 0 0"/>
    <geometry>
      <mesh filename="package://iiwa_gripkit_cr_plus_l_cc_description/meshes/CRG200_body_1.stl" scale="0.001 0.001 0.001"/>
    </geometry>
    <material name="silver"/>
  </visual>
  <collision>
    <origin xyz="-0.046 0.0237 -1.2775" rpy="0 0 0"/>
    <geometry>
      <mesh filename="package://iiwa_gripkit_cr_plus_l_cc_description/meshes/CRG200_body_1.stl" scale="0.001 0.001 0.001"/>
    </geometry>
  </collision>
</link>

<link name="CRG200_base_jaw_1">
  <inertial>
    <origin xyz="-0.001116596745819588 -1.0408340855860843e-16 0.004896836508835323" rpy="0 0 0"/>
    <mass value="0.028974809674202275"/>
    <inertia ixx="0.0" iyy="5e-06" izz="5e-06" ixy="0.0" iyz="-0.0" ixz="0.0"/>
  </inertial>
  <visual>
    <origin xyz="0.0 0.0187 -1.3351" rpy="0 0 0"/>
    <geometry>
      <mesh filename="package://iiwa_gripkit_cr_plus_l_cc_description/meshes/CRG200_base_jaw_1.stl" scale="0.001 0.001 0.001"/>
    </geometry>
    <material name="silver"/>
  </visual>
  <collision>
    <origin xyz="0.0 0.0187 -1.3351" rpy="0 0 0"/>
    <geometry>
      <mesh filename="package://iiwa_gripkit_cr_plus_l_cc_description/meshes/CRG200_base_jaw_1.stl" scale="0.001 0.001 0.001"/>
    </geometry>
  </collision>
</link>

<link name="CRG200_base_jaw__1__1">
  <inertial>
    <origin xyz="0.0011165967458171438 -7.632783294297951e-17 0.004896836508835323" rpy="0 0 0"/>
    <mass value="0.028974809674202275"/>
    <inertia ixx="0.0" iyy="5e-06" izz="5e-06" ixy="0.0" iyz="-0.0" ixz="-0.0"/>
  </inertial>
  <visual>
    <origin xyz="0.0 -0.0183 -1.3351" rpy="0 0 0"/>
    <geometry>
      <mesh filename="package://iiwa_gripkit_cr_plus_l_cc_description/meshes/CRG200_base_jaw__1__1.stl" scale="0.001 0.001 0.001"/>
    </geometry>
    <material name="silver"/>
  </visual>
  <collision>
    <origin xyz="0.0 -0.0183 -1.3351" rpy="0 0 0"/>
    <geometry>
      <mesh filename="package://iiwa_gripkit_cr_plus_l_cc_description/meshes/CRG200_base_jaw__1__1.stl" scale="0.001 0.001 0.001"/>
    </geometry>
  </collision>
</link>

<link name="CRG200_top_cover_1">
  <inertial>
    <origin xyz="-2.837105239211106e-09 7.283818406739586e-09 0.004043925593782083" rpy="0 0 0"/>
    <mass value="0.117790703444327"/>
    <inertia ixx="3.5e-05" iyy="0.000112" izz="0.000144" ixy="-0.0" iyz="-0.0" ixz="0.0"/>
  </inertial>
  <visual>
    <origin xyz="0.0 0.0002 -1.3376" rpy="0 0 0"/>
    <geometry>
      <mesh filename="package://iiwa_gripkit_cr_plus_l_cc_description/meshes/CRG200_top_cover_1.stl" scale="0.001 0.001 0.001"/>
    </geometry>
    <material name="silver"/>
  </visual>
  <collision>
    <origin xyz="0.0 0.0002 -1.3376" rpy="0 0 0"/>
    <geometry>
      <mesh filename="package://iiwa_gripkit_cr_plus_l_cc_description/meshes/CRG200_top_cover_1.stl" scale="0.001 0.001 0.001"/>
    </geometry>
  </collision>
</link>

<link name="ISO_4762_-_M4_x_12ISO_1">
  <inertial>
    <origin xyz="-1.2420620087993939e-15 4.005164255804772e-13 0.0022480078452118413" rpy="0 0 0"/>
    <mass value="0.002203374250243251"/>
    <inertia ixx="0.0" iyy="0.0" izz="0.0" ixy="0.0" iyz="0.0" ixz="0.0"/>
  </inertial>
  <visual>
    <origin xyz="0.046 0.0237 -1.273" rpy="0 0 0"/>
    <geometry>
      <mesh filename="package://iiwa_gripkit_cr_plus_l_cc_description/meshes/ISO_4762_-_M4_x_12ISO_1.stl" scale="0.001 0.001 0.001"/>
    </geometry>
    <material name="silver"/>
  </visual>
  <collision>
    <origin xyz="0.046 0.0237 -1.273" rpy="0 0 0"/>
    <geometry>
      <mesh filename="package://iiwa_gripkit_cr_plus_l_cc_description/meshes/ISO_4762_-_M4_x_12ISO_1.stl" scale="0.001 0.001 0.001"/>
    </geometry>
  </collision>
</link>

<link name="ISO_4762_-_M4_x_12ISO__1__1">
  <inertial>
    <origin xyz="-1.2073675392798577e-15 4.005164255804772e-13 0.0022480078452118413" rpy="0 0 0"/>
    <mass value="0.002203374250243251"/>
    <inertia ixx="0.0" iyy="0.0" izz="0.0" ixy="0.0" iyz="0.0" ixz="0.0"/>
  </inertial>
  <visual>
    <origin xyz="-0.046 0.0237 -1.273" rpy="0 0 0"/>
    <geometry>
      <mesh filename="package://iiwa_gripkit_cr_plus_l_cc_description/meshes/ISO_4762_-_M4_x_12ISO__1__1.stl" scale="0.001 0.001 0.001"/>
    </geometry>
    <material name="silver"/>
  </visual>
  <collision>
    <origin xyz="-0.046 0.0237 -1.273" rpy="0 0 0"/>
    <geometry>
      <mesh filename="package://iiwa_gripkit_cr_plus_l_cc_description/meshes/ISO_4762_-_M4_x_12ISO__1__1.stl" scale="0.001 0.001 0.001"/>
    </geometry>
  </collision>
</link>

<link name="ISO_4762_-_M4_x_12ISO__2__1">
  <inertial>
    <origin xyz="-1.2073675392798577e-15 4.005441811560928e-13 0.0022480078452118413" rpy="0 0 0"/>
    <mass value="0.002203374250243251"/>
    <inertia ixx="0.0" iyy="0.0" izz="0.0" ixy="-0.0" iyz="0.0" ixz="0.0"/>
  </inertial>
  <visual>
    <origin xyz="-0.046 -0.0233 -1.273" rpy="0 0 0"/>
    <geometry>
      <mesh filename="package://iiwa_gripkit_cr_plus_l_cc_description/meshes/ISO_4762_-_M4_x_12ISO__2__1.stl" scale="0.001 0.001 0.001"/>
    </geometry>
    <material name="silver"/>
  </visual>
  <collision>
    <origin xyz="-0.046 -0.0233 -1.273" rpy="0 0 0"/>
    <geometry>
      <mesh filename="package://iiwa_gripkit_cr_plus_l_cc_description/meshes/ISO_4762_-_M4_x_12ISO__2__1.stl" scale="0.001 0.001 0.001"/>
    </geometry>
  </collision>
</link>

<link name="ISO_4762_-_M4_x_12ISO__3__1">
  <inertial>
    <origin xyz="-1.2420620087993939e-15 4.005441811560928e-13 0.0022480078452118413" rpy="0 0 0"/>
    <mass value="0.002203374250243251"/>
    <inertia ixx="0.0" iyy="0.0" izz="0.0" ixy="0.0" iyz="0.0" ixz="0.0"/>
  </inertial>
  <visual>
    <origin xyz="0.046 -0.0233 -1.273" rpy="0 0 0"/>
    <geometry>
      <mesh filename="package://iiwa_gripkit_cr_plus_l_cc_description/meshes/ISO_4762_-_M4_x_12ISO__3__1.stl" scale="0.001 0.001 0.001"/>
    </geometry>
    <material name="silver"/>
  </visual>
  <collision>
    <origin xyz="0.046 -0.0233 -1.273" rpy="0 0 0"/>
    <geometry>
      <mesh filename="package://iiwa_gripkit_cr_plus_l_cc_description/meshes/ISO_4762_-_M4_x_12ISO__3__1.stl" scale="0.001 0.001 0.001"/>
    </geometry>
  </collision>
</link>

<link name="BE_20-030_CUSTOMER_v1_1">
  <inertial>
    <origin xyz="-0.015485870461581964 0.010207189127588086 0.004903018801766246" rpy="0 0 0"/>
    <mass value="0.07101056528211638"/>
    <inertia ixx="7e-06" iyy="8e-06" izz="1.4e-05" ixy="4e-06" iyz="-0.0" ixz="0.0"/>
  </inertial>
  <visual>
    <origin xyz="0.002 0.0187 -1.3475" rpy="0 0 0"/>
    <geometry>
      <mesh filename="package://iiwa_gripkit_cr_plus_l_cc_description/meshes/BE_20-030_CUSTOMER_v1_1.stl" scale="0.001 0.001 0.001"/>
    </geometry>
    <material name="silver"/>
  </visual>
  <collision>
    <origin xyz="0.002 0.0187 -1.3475" rpy="0 0 0"/>
    <geometry>
      <mesh filename="package://iiwa_gripkit_cr_plus_l_cc_description/meshes/BE_20-030_CUSTOMER_v1_1.stl" scale="0.001 0.001 0.001"/>
    </geometry>
  </collision>
</link>

<link name="BE_20-030_CUSTOMER_v1__1__1">
  <inertial>
    <origin xyz="0.015485870461579515 -0.010207189127588246 0.004903018801766246" rpy="0 0 0"/>
    <mass value="0.07101056528211638"/>
    <inertia ixx="7e-06" iyy="8e-06" izz="1.4e-05" ixy="4e-06" iyz="0.0" ixz="-0.0"/>
  </inertial>
  <visual>
    <origin xyz="-0.002 -0.0183 -1.3475" rpy="0 0 0"/>
    <geometry>
      <mesh filename="package://iiwa_gripkit_cr_plus_l_cc_description/meshes/BE_20-030_CUSTOMER_v1__1__1.stl" scale="0.001 0.001 0.001"/>
    </geometry>
    <material name="silver"/>
  </visual>
  <collision>
    <origin xyz="-0.002 -0.0183 -1.3475" rpy="0 0 0"/>
    <geometry>
      <mesh filename="package://iiwa_gripkit_cr_plus_l_cc_description/meshes/BE_20-030_CUSTOMER_v1__1__1.stl" scale="0.001 0.001 0.001"/>
    </geometry>
  </collision>
</link>

<link name="AC_20-025_CUSTOMER_v1_1">
  <inertial>
    <origin xyz="-0.0019437600342800399 -1.16605943650816e-16 0.01432838830627281" rpy="0 0 0"/>
    <mass value="0.07018824497649055"/>
    <inertia ixx="9e-06" iyy="9e-06" izz="4e-06" ixy="-0.0" iyz="-0.0" ixz="1e-06"/>
  </inertial>
  <visual>
    <origin xyz="0.027 0.0002 -1.3575" rpy="0 0 0"/>
    <geometry>
      <mesh filename="package://iiwa_gripkit_cr_plus_l_cc_description/meshes/AC_20-025_CUSTOMER_v1_1.stl" scale="0.001 0.001 0.001"/>
    </geometry>
    <material name="silver"/>
  </visual>
  <collision>
    <origin xyz="0.027 0.0002 -1.3575" rpy="0 0 0"/>
    <geometry>
      <mesh filename="package://iiwa_gripkit_cr_plus_l_cc_description/meshes/AC_20-025_CUSTOMER_v1_1.stl" scale="0.001 0.001 0.001"/>
    </geometry>
  </collision>
</link>

<link name="AC_20-025_CUSTOMER_v1__1__1">
  <inertial>
    <origin xyz="0.0019437600342971685 -7.377995783763858e-17 0.014328388306269924" rpy="0 0 0"/>
    <mass value="0.07018824497649055"/>
    <inertia ixx="9e-06" iyy="9e-06" izz="4e-06" ixy="0.0" iyz="0.0" ixz="-1e-06"/>
  </inertial>
  <visual>
    <origin xyz="-0.027 0.0002 -1.3575" rpy="0 0 0"/>
    <geometry>
      <mesh filename="package://iiwa_gripkit_cr_plus_l_cc_description/meshes/AC_20-025_CUSTOMER_v1__1__1.stl" scale="0.001 0.001 0.001"/>
    </geometry>
    <material name="silver"/>
  </visual>
  <collision>
    <origin xyz="-0.027 0.0002 -1.3575" rpy="0 0 0"/>
    <geometry>
      <mesh filename="package://iiwa_gripkit_cr_plus_l_cc_description/meshes/AC_20-025_CUSTOMER_v1__1__1.stl" scale="0.001 0.001 0.001"/>
    </geometry>
  </collision>
</link>

<link name="FE_20-050_CUSTOMER_v1_1">
  <inertial>
    <origin xyz="6.768003808651016e-05 -0.024908407665588418 -6.661338147750939e-16" rpy="0 0 0"/>
    <mass value="0.11001397809346045"/>
    <inertia ixx="4.4e-05" iyy="8e-06" izz="4.5e-05" ixy="-7e-06" iyz="0.0" ixz="-0.0"/>
  </inertial>
  <visual>
    <origin xyz="0.027 0.0002 -1.3825" rpy="0 0 0"/>
    <geometry>
      <mesh filename="package://iiwa_gripkit_cr_plus_l_cc_description/meshes/FE_20-050_CUSTOMER_v1_1.stl" scale="0.001 0.001 0.001"/>
    </geometry>
    <material name="silver"/>
  </visual>
  <collision>
    <origin xyz="0.027 0.0002 -1.3825" rpy="0 0 0"/>
    <geometry>
      <mesh filename="package://iiwa_gripkit_cr_plus_l_cc_description/meshes/FE_20-050_CUSTOMER_v1_1.stl" scale="0.001 0.001 0.001"/>
    </geometry>
  </collision>
</link>

<link name="FE_20-050_CUSTOMER_v1__1__1">
  <inertial>
    <origin xyz="-6.768003805530595e-05 -0.02490840766558834 -4.440892098500626e-16" rpy="0 0 0"/>
    <mass value="0.11001397809346045"/>
    <inertia ixx="4.4e-05" iyy="8e-06" izz="4.5e-05" ixy="7e-06" iyz="-0.0" ixz="0.0"/>
  </inertial>
  <visual>
    <origin xyz="-0.027 0.0002 -1.3825" rpy="0 0 0"/>
    <geometry>
      <mesh filename="package://iiwa_gripkit_cr_plus_l_cc_description/meshes/FE_20-050_CUSTOMER_v1__1__1.stl" scale="0.001 0.001 0.001"/>
    </geometry>
    <material name="silver"/>
  </visual>
  <collision>
    <origin xyz="-0.027 0.0002 -1.3825" rpy="0 0 0"/>
    <geometry>
      <mesh filename="package://iiwa_gripkit_cr_plus_l_cc_description/meshes/FE_20-050_CUSTOMER_v1__1__1.stl" scale="0.001 0.001 0.001"/>
    </geometry>
  </collision>
</link>

<link name="FT_20-UNI_CUSTOMER_v1_1">
  <inertial>
    <origin xyz="0.009939533936572612 2.2211399386407038e-14 0.00022099286356414005" rpy="0 0 0"/>
    <mass value="0.05314853137521012"/>
    <inertia ixx="3e-06" iyy="3e-06" izz="3e-06" ixy="0.0" iyz="-0.0" ixz="-0.0"/>
  </inertial>
  <visual>
    <origin xyz="0.027 0.0502 -1.3825" rpy="0 0 0"/>
    <geometry>
      <mesh filename="package://iiwa_gripkit_cr_plus_l_cc_description/meshes/FT_20-UNI_CUSTOMER_v1_1.stl" scale="0.001 0.001 0.001"/>
    </geometry>
    <material name="silver"/>
  </visual>
  <collision>
    <origin xyz="0.027 0.0502 -1.3825" rpy="0 0 0"/>
    <geometry>
      <mesh filename="package://iiwa_gripkit_cr_plus_l_cc_description/meshes/FT_20-UNI_CUSTOMER_v1_1.stl" scale="0.001 0.001 0.001"/>
    </geometry>
  </collision>
</link>

<link name="FT_20-UNI_CUSTOMER_v1__1__1">
  <inertial>
    <origin xyz="-0.009939533936541622 -2.2412627309620348e-14 0.0002209928635783509" rpy="0 0 0"/>
    <mass value="0.05314853137521012"/>
    <inertia ixx="3e-06" iyy="3e-06" izz="3e-06" ixy="0.0" iyz="0.0" ixz="0.0"/>
  </inertial>
  <visual>
    <origin xyz="-0.027 0.0502 -1.3825" rpy="0 0 0"/>
    <geometry>
      <mesh filename="package://iiwa_gripkit_cr_plus_l_cc_description/meshes/FT_20-UNI_CUSTOMER_v1__1__1.stl" scale="0.001 0.001 0.001"/>
    </geometry>
    <material name="silver"/>
  </visual>
  <collision>
    <origin xyz="-0.027 0.0502 -1.3825" rpy="0 0 0"/>
    <geometry>
      <mesh filename="package://iiwa_gripkit_cr_plus_l_cc_description/meshes/FT_20-UNI_CUSTOMER_v1__1__1.stl" scale="0.001 0.001 0.001"/>
    </geometry>
  </collision>
</link>

<link name="link_1_1">
  <inertial>
    <origin xyz="9.615003024343416e-08 -0.03473351023743466 0.12351616001638635" rpy="0 0 0"/>
    <mass value="21.213888253656222"/>
    <inertia ixx="0.13413" iyy="0.127957" izz="0.047327" ixy="0.0" iyz="0.023881" ixz="0.0"/>
  </inertial>
  <visual>
    <origin xyz="-0.0 0.0 -0.1475" rpy="0 0 0"/>
    <geometry>
      <mesh filename="package://iiwa_gripkit_cr_plus_l_cc_description/meshes/link_1_1.stl" scale="0.001 0.001 0.001"/>
    </geometry>
    <material name="silver"/>
  </visual>
  <collision>
    <origin xyz="-0.0 0.0 -0.1475" rpy="0 0 0"/>
    <geometry>
      <mesh filename="package://iiwa_gripkit_cr_plus_l_cc_description/meshes/link_1_1.stl" scale="0.001 0.001 0.001"/>
    </geometry>
  </collision>
</link>

<link name="link_2_1">
  <inertial>
    <origin xyz="5.3961961621630917e-08 0.04491512185097363 0.06732557420480756" rpy="0 0 0"/>
    <mass value="21.397098230942653"/>
    <inertia ixx="0.133838" iyy="0.127529" izz="0.047851" ixy="-0.0" iyz="0.02227" ixz="0.0"/>
  </inertial>
  <visual>
    <origin xyz="0.0 0.0105 -0.3405" rpy="0 0 0"/>
    <geometry>
      <mesh filename="package://iiwa_gripkit_cr_plus_l_cc_description/meshes/link_2_1.stl" scale="0.001 0.001 0.001"/>
    </geometry>
    <material name="silver"/>
  </visual>
  <collision>
    <origin xyz="0.0 0.0105 -0.3405" rpy="0 0 0"/>
    <geometry>
      <mesh filename="package://iiwa_gripkit_cr_plus_l_cc_description/meshes/link_2_1.stl" scale="0.001 0.001 0.001"/>
    </geometry>
  </collision>
</link>

<link name="link_3_1">
  <inertial>
    <origin xyz="1.207224751269193e-08 0.029563686162089268 0.13650353945673122" rpy="0 0 0"/>
    <mass value="24.923668408341197"/>
    <inertia ixx="0.196866" iyy="0.186887" izz="0.059721" ixy="-0.0" iyz="-0.038259" ixz="-0.0"/>
  </inertial>
  <visual>
    <origin xyz="0.0 0.0 -0.515" rpy="0 0 0"/>
    <geometry>
      <mesh filename="package://iiwa_gripkit_cr_plus_l_cc_description/meshes/link_3_1.stl" scale="0.001 0.001 0.001"/>
    </geometry>
    <material name="silver"/>
  </visual>
  <collision>
    <origin xyz="0.0 0.0 -0.515" rpy="0 0 0"/>
    <geometry>
      <mesh filename="package://iiwa_gripkit_cr_plus_l_cc_description/meshes/link_3_1.stl" scale="0.001 0.001 0.001"/>
    </geometry>
  </collision>
</link>

<link name="link_4_1">
  <inertial>
    <origin xyz="-5.485084286249875e-08 -0.044915740111597394 0.06732540221831629" rpy="0 0 0"/>
    <mass value="21.397084006482324"/>
    <inertia ixx="0.133811" iyy="0.127521" izz="0.047832" ixy="0.0" iyz="-0.022267" ixz="-0.0"/>
  </inertial>
  <visual>
    <origin xyz="0.0 -0.0105 -0.7405" rpy="0 0 0"/>
    <geometry>
      <mesh filename="package://iiwa_gripkit_cr_plus_l_cc_description/meshes/link_4_1.stl" scale="0.001 0.001 0.001"/>
    </geometry>
    <material name="silver"/>
  </visual>
  <collision>
    <origin xyz="0.0 -0.0105 -0.7405" rpy="0 0 0"/>
    <geometry>
      <mesh filename="package://iiwa_gripkit_cr_plus_l_cc_description/meshes/link_4_1.stl" scale="0.001 0.001 0.001"/>
    </geometry>
  </collision>
</link>

<link name="link_5_1">
  <inertial>
    <origin xyz="-8.834784191987874e-09 -0.02138659031332106 0.08546853677464128" rpy="0 0 0"/>
    <mass value="13.296685148643036"/>
    <inertia ixx="0.079123" iyy="0.068318" izz="0.035085" ixy="-0.0" iyz="0.024261" ixz="0.0"/>
  </inertial>
  <visual>
    <origin xyz="0.0 0.0 -0.915" rpy="0 0 0"/>
    <geometry>
      <mesh filename="package://iiwa_gripkit_cr_plus_l_cc_description/meshes/link_5_1.stl" scale="0.001 0.001 0.001"/>
    </geometry>
    <material name="silver"/>
  </visual>
  <collision>
    <origin xyz="0.0 0.0 -0.915" rpy="0 0 0"/>
    <geometry>
      <mesh filename="package://iiwa_gripkit_cr_plus_l_cc_description/meshes/link_5_1.stl" scale="0.001 0.001 0.001"/>
    </geometry>
  </collision>
</link>

<link name="link_6_1">
  <inertial>
    <origin xyz="-2.784005425984457e-07 0.07098688488077398 0.002115616520607766" rpy="0 0 0"/>
    <mass value="14.421198781272748"/>
    <inertia ixx="0.040001" iyy="0.038461" izz="0.027817" ixy="0.0" iyz="0.00196" ixz="0.0"/>
  </inertial>
  <visual>
    <origin xyz="0.0 0.0707 -1.1405" rpy="0 0 0"/>
    <geometry>
      <mesh filename="package://iiwa_gripkit_cr_plus_l_cc_description/meshes/link_6_1.stl" scale="0.001 0.001 0.001"/>
    </geometry>
    <material name="silver"/>
  </visual>
  <collision>
    <origin xyz="0.0 0.0707 -1.1405" rpy="0 0 0"/>
    <geometry>
      <mesh filename="package://iiwa_gripkit_cr_plus_l_cc_description/meshes/link_6_1.stl" scale="0.001 0.001 0.001"/>
    </geometry>
  </collision>
</link>

<link name="flange_1">
  <inertial>
    <origin xyz="4.659054144324853e-06 1.7291653306211654e-08 0.009981852938580671" rpy="0 0 0"/>
    <mass value="2.1030620192288976"/>
    <inertia ixx="0.001534" iyy="0.001534" izz="0.00251" ixy="-1.5e-05" iyz="-0.0" ixz="-0.0"/>
  </inertial>
  <visual>
    <origin xyz="0.0 0.0002 -1.2314" rpy="0 0 0"/>
    <geometry>
      <mesh filename="package://iiwa_gripkit_cr_plus_l_cc_description/meshes/flange_1.stl" scale="0.001 0.001 0.001"/>
    </geometry>
    <material name="silver"/>
  </visual>
  <collision>
    <origin xyz="0.0 0.0002 -1.2314" rpy="0 0 0"/>
    <geometry>
      <mesh filename="package://iiwa_gripkit_cr_plus_l_cc_description/meshes/flange_1.stl" scale="0.001 0.001 0.001"/>
    </geometry>
  </collision>
</link>

<joint name="base_footprint_joint" type="fixed">
  <origin xyz="0 0 0" rpy="0 0 0"/>
  <parent link="base_footprint"/>
  <child link="base_link"/>
</joint>

<joint name="Rigid18" type="fixed">
  <origin xyz="-5e-06 -0.050302 0.01703" rpy="0 0 0"/>
  <parent link="flange_1"/>
  <child link="screw_1_1"/>
</joint>

<joint name="Rigid19" type="fixed">
  <origin xyz="-0.050305 -2e-06 0.01703" rpy="0 0 0"/>
  <parent link="flange_1"/>
  <child link="screw_2_1"/>
</joint>

<joint name="Rigid20" type="fixed">
  <origin xyz="-5e-06 0.050298 0.01703" rpy="0 0 0"/>
  <parent link="flange_1"/>
  <child link="screw_3_1"/>
</joint>

<joint name="Rigid21" type="fixed">
  <origin xyz="0.050295 -2e-06 0.01703" rpy="0 0 0"/>
  <parent link="flange_1"/>
  <child link="screw_4_1"/>
</joint>

<joint name="Rigid22" type="fixed">
  <origin xyz="0.035567 -0.035567 0.0121" rpy="0 0 0"/>
  <parent link="flange_1"/>
  <child link="screw_5_1"/>
</joint>

<joint name="Rigid23" type="fixed">
  <origin xyz="-0.035567 0.035567 0.0121" rpy="0 0 0"/>
  <parent link="flange_1"/>
  <child link="screw_6_1"/>
</joint>

<joint name="Rigid24" type="fixed">
  <origin xyz="0.0 -0.025 0.0351" rpy="0 0 0"/>
  <parent link="flange_1"/>
  <child link="SF-ISO50-CRG200_Customer_1"/>
</joint>

<joint name="Rigid25" type="fixed">
  <origin xyz="0.046 0.0015 0.011" rpy="0 0 0"/>
  <parent link="SF-ISO50-CRG200_Customer_1"/>
  <child link="CRG200_body_1"/>
</joint>

<joint name="Slider26" type="prismatic">
  <origin xyz="-0.046 0.005 0.0576" rpy="0 0 0"/>
  <parent link="CRG200_body_1"/>
  <child link="CRG200_base_jaw_1"/>
  <axis xyz="1.0 0.0 0.0"/>
  <limit upper="0.021" lower="-0.021" effort="100" velocity="100"/>
</joint>

<joint name="Slider27" type="prismatic">
  <origin xyz="-0.046 0.042 0.0576" rpy="0 0 0"/>
  <parent link="CRG200_body_1"/>
  <child link="CRG200_base_jaw__1__1"/>
  <axis xyz="1.0 0.0 0.0"/>
  <limit upper="0.021" lower="-0.021" effort="100" velocity="100"/>
</joint>

<joint name="Rigid28" type="fixed">
  <origin xyz="-0.046 0.0235 0.0601" rpy="0 0 0"/>
  <parent link="CRG200_body_1"/>
  <child link="CRG200_top_cover_1"/>
</joint>

<joint name="Rigid29" type="fixed">
  <origin xyz="-0.046 0.0015 0.0065" rpy="0 0 0"/>
  <parent link="SF-ISO50-CRG200_Customer_1"/>
  <child link="ISO_4762_-_M4_x_12ISO_1"/>
</joint>

<joint name="Rigid30" type="fixed">
  <origin xyz="0.046 0.0015 0.0065" rpy="0 0 0"/>
  <parent link="SF-ISO50-CRG200_Customer_1"/>
  <child link="ISO_4762_-_M4_x_12ISO__1__1"/>
</joint>

<joint name="Rigid31" type="fixed">
  <origin xyz="0.046 0.0485 0.0065" rpy="0 0 0"/>
  <parent link="SF-ISO50-CRG200_Customer_1"/>
  <child link="ISO_4762_-_M4_x_12ISO__2__1"/>
</joint>

<joint name="Rigid32" type="fixed">
  <origin xyz="-0.046 0.0485 0.0065" rpy="0 0 0"/>
  <parent link="SF-ISO50-CRG200_Customer_1"/>
  <child link="ISO_4762_-_M4_x_12ISO__3__1"/>
</joint>

<joint name="Rigid33" type="fixed">
  <origin xyz="-0.002 0.0 0.0124" rpy="0 0 0"/>
  <parent link="CRG200_base_jaw_1"/>
  <child link="BE_20-030_CUSTOMER_v1_1"/>
</joint>

<joint name="Rigid34" type="fixed">
  <origin xyz="0.002 0.0 0.0124" rpy="0 0 0"/>
  <parent link="CRG200_base_jaw__1__1"/>
  <child link="BE_20-030_CUSTOMER_v1__1__1"/>
</joint>

<joint name="Rigid35" type="fixed">
  <origin xyz="-0.025 0.0185 0.01" rpy="0 0 0"/>
  <parent link="BE_20-030_CUSTOMER_v1_1"/>
  <child link="AC_20-025_CUSTOMER_v1_1"/>
</joint>

<joint name="Rigid36" type="fixed">
  <origin xyz="0.025 -0.0185 0.01" rpy="0 0 0"/>
  <parent link="BE_20-030_CUSTOMER_v1__1__1"/>
  <child link="AC_20-025_CUSTOMER_v1__1__1"/>
</joint>

<joint name="Rigid41" type="fixed">
  <origin xyz="0.0 0.0 0.025" rpy="0 0 0"/>
  <parent link="AC_20-025_CUSTOMER_v1_1"/>
  <child link="FE_20-050_CUSTOMER_v1_1"/>
</joint>

<joint name="Rigid42" type="fixed">
  <origin xyz="0.0 0.0 0.025" rpy="0 0 0"/>
  <parent link="AC_20-025_CUSTOMER_v1__1__1"/>
  <child link="FE_20-050_CUSTOMER_v1__1__1"/>
</joint>

<joint name="Rigid43" type="fixed">
  <origin xyz="0.0 -0.05 0.0" rpy="0 0 0"/>
  <parent link="FE_20-050_CUSTOMER_v1_1"/>
  <child link="FT_20-UNI_CUSTOMER_v1_1"/>
</joint>

<joint name="Rigid44" type="fixed">
  <origin xyz="0.0 -0.05 0.0" rpy="0 0 0"/>
  <parent link="FE_20-050_CUSTOMER_v1__1__1"/>
  <child link="FT_20-UNI_CUSTOMER_v1__1__1"/>
</joint>

<joint name="Rev45" type="revolute">
  <origin xyz="0.0 0.0 0.1475" rpy="0 0 0"/>
  <parent link="base_link"/>
  <child link="link_1_1"/>
  <axis xyz="0.0 0.0 1.0"/>
  <limit upper="2.96706" lower="-2.96706" effort="100" velocity="100"/>
</joint>

<joint name="Rev46" type="revolute">
  <origin xyz="-0.0 -0.0105 0.193" rpy="0 0 0"/>
  <parent link="link_1_1"/>
  <child link="link_2_1"/>
  <axis xyz="0.0 1.0 0.0"/>
  <limit upper="2.094395" lower="-2.094395" effort="100" velocity="100"/>
</joint>

<joint name="Rev47" type="revolute">
  <origin xyz="0.0 0.0105 0.1745" rpy="0 0 0"/>
  <parent link="link_2_1"/>
  <child link="link_3_1"/>
  <axis xyz="0.0 0.0 1.0"/>
  <limit upper="2.96706" lower="-2.96706" effort="100" velocity="100"/>
</joint>

<joint name="Rev48" type="revolute">
  <origin xyz="0.0 0.0105 0.2255" rpy="0 0 0"/>
  <parent link="link_3_1"/>
  <child link="link_4_1"/>
  <axis xyz="0.0 -1.0 0.0"/>
  <limit upper="2.094395" lower="-2.094395" effort="100" velocity="100"/>
</joint>

<joint name="Rev49" type="revolute">
  <origin xyz="0.0 -0.0105 0.1745" rpy="0 0 0"/>
  <parent link="link_4_1"/>
  <child link="link_5_1"/>
  <axis xyz="0.0 0.0 1.0"/>
  <limit upper="2.96706" lower="-2.96706" effort="100" velocity="100"/>
</joint>

<joint name="Rev50" type="revolute">
  <origin xyz="0.0 -0.0707 0.2255" rpy="0 0 0"/>
  <parent link="link_5_1"/>
  <child link="link_6_1"/>
  <axis xyz="0.0 1.0 0.0"/>
  <limit upper="2.094395" lower="-2.094395" effort="100" velocity="100"/>
</joint>

<joint name="Rev51" type="revolute">
  <origin xyz="0.0 0.0705 0.0909" rpy="0 0 0"/>
  <parent link="link_6_1"/>
  <child link="flange_1"/>
  <axis xyz="0.0 0.0 1.0"/>
  <limit upper="3.054326" lower="-3.054326" effort="100" velocity="100"/>
</joint>

</robot>
