<?xml version="1.0" ?>
<robot name="kmr_iiwa_gripkit_cr_plus_l_dd" xmlns:xacro="http://www.ros.org/wiki/xacro">

<xacro:include filename="$(find kmr_iiwa_gripkit_cr_plus_l_dd_description)/urdf/materials.xacro" />
<xacro:include filename="$(find kmr_iiwa_gripkit_cr_plus_l_dd_description)/urdf/kmr_iiwa_gripkit_cr_plus_l_dd.trans" />
<xacro:include filename="$(find kmr_iiwa_gripkit_cr_plus_l_dd_description)/urdf/kmr_iiwa_gripkit_cr_plus_l_dd.gazebo" />
<link name="base_footprint">
</link>
<link name="base_link">
  <inertial>
    <origin xyz="-0.022925412948107512 0.00038108208357065076 0.36430343293578027" rpy="0 0 0"/>
    <mass value="3266.3922537057438"/>
    <inertia ixx="226.744522" iyy="400.752195" izz="384.998869" ixy="-2.223757" iyz="-1.110451" ixz="10.295288"/>
  </inertial>
  <visual>
    <origin xyz="0 0 0" rpy="0 0 0"/>
    <geometry>
      <mesh filename="package://kmr_iiwa_gripkit_cr_plus_l_dd_description/meshes/base_link.stl" scale="0.001 0.001 0.001"/>
    </geometry>
    <material name="silver"/>
  </visual>
  <collision>
    <origin xyz="0 0 0" rpy="0 0 0"/>
    <geometry>
      <mesh filename="package://kmr_iiwa_gripkit_cr_plus_l_dd_description/meshes/base_link.stl" scale="0.001 0.001 0.001"/>
    </geometry>
  </collision>
</link>

<link name="cover_1">
  <inertial>
    <origin xyz="0.013260016215843495 4.4670223014499355e-07 -0.22267526504937868" rpy="0 0 0"/>
    <mass value="7.737707490873716"/>
    <inertia ixx="0.059177" iyy="0.024648" izz="0.03712" ixy="0.0" iyz="-0.0" ixz="0.001342"/>
  </inertial>
  <visual>
    <origin xyz="-0.532642 0.001456 -0.642155" rpy="0 0 0"/>
    <geometry>
      <mesh filename="package://kmr_iiwa_gripkit_cr_plus_l_dd_description/meshes/cover_1.stl" scale="0.001 0.001 0.001"/>
    </geometry>
    <material name="silver"/>
  </visual>
  <collision>
    <origin xyz="-0.532642 0.001456 -0.642155" rpy="0 0 0"/>
    <geometry>
      <mesh filename="package://kmr_iiwa_gripkit_cr_plus_l_dd_description/meshes/cover_1.stl" scale="0.001 0.001 0.001"/>
    </geometry>
  </collision>
</link>

<link name="screw_1_1">
  <inertial>
    <origin xyz="-0.0010385144736145824 1.484096824061476e-05 6.0707873601462126e-06" rpy="0 0 0"/>
    <mass value="0.002693161929654313"/>
    <inertia ixx="0.0" iyy="0.0" izz="0.0" ixy="-0.0" iyz="0.0" ixz="-0.0"/>
  </inertial>
  <visual>
    <origin xyz="-0.305141 0.185451 -1.948785" rpy="0 0 0"/>
    <geometry>
      <mesh filename="package://kmr_iiwa_gripkit_cr_plus_l_dd_description/meshes/screw_1_1.stl" scale="0.001 0.001 0.001"/>
    </geometry>
    <material name="silver"/>
  </visual>
  <collision>
    <origin xyz="-0.305141 0.185451 -1.948785" rpy="0 0 0"/>
    <geometry>
      <mesh filename="package://kmr_iiwa_gripkit_cr_plus_l_dd_description/meshes/screw_1_1.stl" scale="0.001 0.001 0.001"/>
    </geometry>
  </collision>
</link>

<link name="screw_2_1">
  <inertial>
    <origin xyz="3.721787165678059e-07 0.001037868287873417 -1.6786964759152312e-05" rpy="0 0 0"/>
    <mass value="0.0026932173030154573"/>
    <inertia ixx="0.0" iyy="0.0" izz="0.0" ixy="0.0" iyz="-0.0" ixz="0.0"/>
  </inertial>
  <visual>
    <origin xyz="-0.355441 0.135151 -1.948785" rpy="0 0 0"/>
    <geometry>
      <mesh filename="package://kmr_iiwa_gripkit_cr_plus_l_dd_description/meshes/screw_2_1.stl" scale="0.001 0.001 0.001"/>
    </geometry>
    <material name="silver"/>
  </visual>
  <collision>
    <origin xyz="-0.355441 0.135151 -1.948785" rpy="0 0 0"/>
    <geometry>
      <mesh filename="package://kmr_iiwa_gripkit_cr_plus_l_dd_description/meshes/screw_2_1.stl" scale="0.001 0.001 0.001"/>
    </geometry>
  </collision>
</link>

<link name="screw_3_1">
  <inertial>
    <origin xyz="0.0010370860703485252 4.157579670677203e-06 1.5286181210383276e-05" rpy="0 0 0"/>
    <mass value="0.002693745664184645"/>
    <inertia ixx="0.0" iyy="0.0" izz="0.0" ixy="0.0" iyz="0.0" ixz="0.0"/>
  </inertial>
  <visual>
    <origin xyz="-0.405741 0.185451 -1.948785" rpy="0 0 0"/>
    <geometry>
      <mesh filename="package://kmr_iiwa_gripkit_cr_plus_l_dd_description/meshes/screw_3_1.stl" scale="0.001 0.001 0.001"/>
    </geometry>
    <material name="silver"/>
  </visual>
  <collision>
    <origin xyz="-0.405741 0.185451 -1.948785" rpy="0 0 0"/>
    <geometry>
      <mesh filename="package://kmr_iiwa_gripkit_cr_plus_l_dd_description/meshes/screw_3_1.stl" scale="0.001 0.001 0.001"/>
    </geometry>
  </collision>
</link>

<link name="screw_4_1">
  <inertial>
    <origin xyz="-1.6576839376281072e-05 -0.0010378936134272376 -1.964673214782664e-06" rpy="0 0 0"/>
    <mass value="0.0026933743563882172"/>
    <inertia ixx="0.0" iyy="0.0" izz="0.0" ixy="0.0" iyz="-0.0" ixz="0.0"/>
  </inertial>
  <visual>
    <origin xyz="-0.355441 0.235751 -1.948785" rpy="0 0 0"/>
    <geometry>
      <mesh filename="package://kmr_iiwa_gripkit_cr_plus_l_dd_description/meshes/screw_4_1.stl" scale="0.001 0.001 0.001"/>
    </geometry>
    <material name="silver"/>
  </visual>
  <collision>
    <origin xyz="-0.355441 0.235751 -1.948785" rpy="0 0 0"/>
    <geometry>
      <mesh filename="package://kmr_iiwa_gripkit_cr_plus_l_dd_description/meshes/screw_4_1.stl" scale="0.001 0.001 0.001"/>
    </geometry>
  </collision>
</link>

<link name="screw_5_1">
  <inertial>
    <origin xyz="-0.0007450074042782417 -0.000722389900242093 -5.329976793255753e-07" rpy="0 0 0"/>
    <mass value="0.002693701452940877"/>
    <inertia ixx="0.0" iyy="0.0" izz="0.0" ixy="-0.0" iyz="-0.0" ixz="0.0"/>
  </inertial>
  <visual>
    <origin xyz="-0.319875 0.221023 -1.943855" rpy="0 0 0"/>
    <geometry>
      <mesh filename="package://kmr_iiwa_gripkit_cr_plus_l_dd_description/meshes/screw_5_1.stl" scale="0.001 0.001 0.001"/>
    </geometry>
    <material name="silver"/>
  </visual>
  <collision>
    <origin xyz="-0.319875 0.221023 -1.943855" rpy="0 0 0"/>
    <geometry>
      <mesh filename="package://kmr_iiwa_gripkit_cr_plus_l_dd_description/meshes/screw_5_1.stl" scale="0.001 0.001 0.001"/>
    </geometry>
  </collision>
</link>

<link name="screw_6_1">
  <inertial>
    <origin xyz="0.0007222088301764851 0.0007456857271478101 2.0216985636700713e-06" rpy="0 0 0"/>
    <mass value="0.0026933936118932553"/>
    <inertia ixx="0.0" iyy="0.0" izz="0.0" ixy="-0.0" iyz="0.0" ixz="-0.0"/>
  </inertial>
  <visual>
    <origin xyz="-0.39101 0.149889 -1.943855" rpy="0 0 0"/>
    <geometry>
      <mesh filename="package://kmr_iiwa_gripkit_cr_plus_l_dd_description/meshes/screw_6_1.stl" scale="0.001 0.001 0.001"/>
    </geometry>
    <material name="silver"/>
  </visual>
  <collision>
    <origin xyz="-0.39101 0.149889 -1.943855" rpy="0 0 0"/>
    <geometry>
      <mesh filename="package://kmr_iiwa_gripkit_cr_plus_l_dd_description/meshes/screw_6_1.stl" scale="0.001 0.001 0.001"/>
    </geometry>
  </collision>
</link>

<link name="SF-ISO50-CRG200_Customer_1">
  <inertial>
    <origin xyz="0.025000490681773513 0.0008393954405518378 0.005627348732812676" rpy="0 0 0"/>
    <mass value="0.16831092346442011"/>
    <inertia ixx="0.000144" iyy="5.7e-05" izz="0.000197" ixy="0.0" iyz="-1e-06" ixz="0.0"/>
  </inertial>
  <visual>
    <origin xyz="-0.330442 0.185456 -1.966855" rpy="0 0 0"/>
    <geometry>
      <mesh filename="package://kmr_iiwa_gripkit_cr_plus_l_dd_description/meshes/SF-ISO50-CRG200_Customer_1.stl" scale="0.001 0.001 0.001"/>
    </geometry>
    <material name="silver"/>
  </visual>
  <collision>
    <origin xyz="-0.330442 0.185456 -1.966855" rpy="0 0 0"/>
    <geometry>
      <mesh filename="package://kmr_iiwa_gripkit_cr_plus_l_dd_description/meshes/SF-ISO50-CRG200_Customer_1.stl" scale="0.001 0.001 0.001"/>
    </geometry>
  </collision>
</link>

<link name="CRG200_body_1">
  <inertial>
    <origin xyz="0.02350040445755147 0.04601342771753081 0.029718925678388075" rpy="0 0 0"/>
    <mass value="1.024019455093708"/>
    <inertia ixx="0.001224" iyy="0.000598" izz="0.001229" ixy="-0.0" iyz="0.0" ixz="-0.0"/>
  </inertial>
  <visual>
    <origin xyz="-0.331942 0.231456 -1.977855" rpy="0 0 0"/>
    <geometry>
      <mesh filename="package://kmr_iiwa_gripkit_cr_plus_l_dd_description/meshes/CRG200_body_1.stl" scale="0.001 0.001 0.001"/>
    </geometry>
    <material name="silver"/>
  </visual>
  <collision>
    <origin xyz="-0.331942 0.231456 -1.977855" rpy="0 0 0"/>
    <geometry>
      <mesh filename="package://kmr_iiwa_gripkit_cr_plus_l_dd_description/meshes/CRG200_body_1.stl" scale="0.001 0.001 0.001"/>
    </geometry>
  </collision>
</link>

<link name="CRG200_base_jaw_1">
  <inertial>
    <origin xyz="3.5799715114581687e-07 0.001116604941052951 0.00489638531674208" rpy="0 0 0"/>
    <mass value="0.028974809674202275"/>
    <inertia ixx="5e-06" iyy="0.0" izz="5e-06" ixy="0.0" iyz="-0.0" ixz="0.0"/>
  </inertial>
  <visual>
    <origin xyz="-0.336942 0.185456 -2.035455" rpy="0 0 0"/>
    <geometry>
      <mesh filename="package://kmr_iiwa_gripkit_cr_plus_l_dd_description/meshes/CRG200_base_jaw_1.stl" scale="0.001 0.001 0.001"/>
    </geometry>
    <material name="silver"/>
  </visual>
  <collision>
    <origin xyz="-0.336942 0.185456 -2.035455" rpy="0 0 0"/>
    <geometry>
      <mesh filename="package://kmr_iiwa_gripkit_cr_plus_l_dd_description/meshes/CRG200_base_jaw_1.stl" scale="0.001 0.001 0.001"/>
    </geometry>
  </collision>
</link>

<link name="CRG200_base_jaw__1__1">
  <inertial>
    <origin xyz="3.579971514788838e-07 -0.0011165885505837192 0.00489638531674208" rpy="0 0 0"/>
    <mass value="0.028974809674202275"/>
    <inertia ixx="5e-06" iyy="0.0" izz="5e-06" ixy="0.0" iyz="0.0" ixz="0.0"/>
  </inertial>
  <visual>
    <origin xyz="-0.373942 0.185456 -2.035455" rpy="0 0 0"/>
    <geometry>
      <mesh filename="package://kmr_iiwa_gripkit_cr_plus_l_dd_description/meshes/CRG200_base_jaw__1__1.stl" scale="0.001 0.001 0.001"/>
    </geometry>
    <material name="silver"/>
  </visual>
  <collision>
    <origin xyz="-0.373942 0.185456 -2.035455" rpy="0 0 0"/>
    <geometry>
      <mesh filename="package://kmr_iiwa_gripkit_cr_plus_l_dd_description/meshes/CRG200_base_jaw__1__1.stl" scale="0.001 0.001 0.001"/>
    </geometry>
  </collision>
</link>

<link name="CRG200_top_cover_1">
  <inertial>
    <origin xyz="3.65280969638615e-07 1.103233868149367e-08 0.004043474401688396" rpy="0 0 0"/>
    <mass value="0.117790703444327"/>
    <inertia ixx="0.000112" iyy="3.5e-05" izz="0.000144" ixy="0.0" iyz="-0.0" ixz="-0.0"/>
  </inertial>
  <visual>
    <origin xyz="-0.355442 0.185456 -2.037955" rpy="0 0 0"/>
    <geometry>
      <mesh filename="package://kmr_iiwa_gripkit_cr_plus_l_dd_description/meshes/CRG200_top_cover_1.stl" scale="0.001 0.001 0.001"/>
    </geometry>
    <material name="silver"/>
  </visual>
  <collision>
    <origin xyz="-0.355442 0.185456 -2.037955" rpy="0 0 0"/>
    <geometry>
      <mesh filename="package://kmr_iiwa_gripkit_cr_plus_l_dd_description/meshes/CRG200_top_cover_1.stl" scale="0.001 0.001 0.001"/>
    </geometry>
  </collision>
</link>

<link name="ISO_4762_-_M4_x_12ISO_1">
  <inertial>
    <origin xyz="3.5799755160326185e-07 8.195234019181541e-09 0.002247556653119487" rpy="0 0 0"/>
    <mass value="0.002203374250243251"/>
    <inertia ixx="0.0" iyy="0.0" izz="0.0" ixy="0.0" iyz="0.0" ixz="0.0"/>
  </inertial>
  <visual>
    <origin xyz="-0.331942 0.139456 -1.973355" rpy="0 0 0"/>
    <geometry>
      <mesh filename="package://kmr_iiwa_gripkit_cr_plus_l_dd_description/meshes/ISO_4762_-_M4_x_12ISO_1.stl" scale="0.001 0.001 0.001"/>
    </geometry>
    <material name="silver"/>
  </visual>
  <collision>
    <origin xyz="-0.331942 0.139456 -1.973355" rpy="0 0 0"/>
    <geometry>
      <mesh filename="package://kmr_iiwa_gripkit_cr_plus_l_dd_description/meshes/ISO_4762_-_M4_x_12ISO_1.stl" scale="0.001 0.001 0.001"/>
    </geometry>
  </collision>
</link>

<link name="ISO_4762_-_M4_x_12ISO__1__1">
  <inertial>
    <origin xyz="3.5799755160326185e-07 8.195234268981721e-09 0.002247556653119487" rpy="0 0 0"/>
    <mass value="0.002203374250243251"/>
    <inertia ixx="0.0" iyy="0.0" izz="0.0" ixy="-0.0" iyz="0.0" ixz="0.0"/>
  </inertial>
  <visual>
    <origin xyz="-0.331942 0.231456 -1.973355" rpy="0 0 0"/>
    <geometry>
      <mesh filename="package://kmr_iiwa_gripkit_cr_plus_l_dd_description/meshes/ISO_4762_-_M4_x_12ISO__1__1.stl" scale="0.001 0.001 0.001"/>
    </geometry>
    <material name="silver"/>
  </visual>
  <collision>
    <origin xyz="-0.331942 0.231456 -1.973355" rpy="0 0 0"/>
    <geometry>
      <mesh filename="package://kmr_iiwa_gripkit_cr_plus_l_dd_description/meshes/ISO_4762_-_M4_x_12ISO__1__1.stl" scale="0.001 0.001 0.001"/>
    </geometry>
  </collision>
</link>

<link name="ISO_4762_-_M4_x_12ISO__2__1">
  <inertial>
    <origin xyz="3.5799755193632876e-07 8.1952344077596e-09 0.002247556653119487" rpy="0 0 0"/>
    <mass value="0.002203374250243251"/>
    <inertia ixx="0.0" iyy="0.0" izz="0.0" ixy="-0.0" iyz="0.0" ixz="0.0"/>
  </inertial>
  <visual>
    <origin xyz="-0.378942 0.231456 -1.973355" rpy="0 0 0"/>
    <geometry>
      <mesh filename="package://kmr_iiwa_gripkit_cr_plus_l_dd_description/meshes/ISO_4762_-_M4_x_12ISO__2__1.stl" scale="0.001 0.001 0.001"/>
    </geometry>
    <material name="silver"/>
  </visual>
  <collision>
    <origin xyz="-0.378942 0.231456 -1.973355" rpy="0 0 0"/>
    <geometry>
      <mesh filename="package://kmr_iiwa_gripkit_cr_plus_l_dd_description/meshes/ISO_4762_-_M4_x_12ISO__2__1.stl" scale="0.001 0.001 0.001"/>
    </geometry>
  </collision>
</link>

<link name="ISO_4762_-_M4_x_12ISO__3__1">
  <inertial>
    <origin xyz="3.579975521028622e-07 8.195234130203843e-09 0.002247556653119487" rpy="0 0 0"/>
    <mass value="0.002203374250243251"/>
    <inertia ixx="0.0" iyy="0.0" izz="0.0" ixy="-0.0" iyz="0.0" ixz="0.0"/>
  </inertial>
  <visual>
    <origin xyz="-0.378942 0.139456 -1.973355" rpy="0 0 0"/>
    <geometry>
      <mesh filename="package://kmr_iiwa_gripkit_cr_plus_l_dd_description/meshes/ISO_4762_-_M4_x_12ISO__3__1.stl" scale="0.001 0.001 0.001"/>
    </geometry>
    <material name="silver"/>
  </visual>
  <collision>
    <origin xyz="-0.378942 0.139456 -1.973355" rpy="0 0 0"/>
    <geometry>
      <mesh filename="package://kmr_iiwa_gripkit_cr_plus_l_dd_description/meshes/ISO_4762_-_M4_x_12ISO__3__1.stl" scale="0.001 0.001 0.001"/>
    </geometry>
  </collision>
</link>

<link name="BE_20-030_CUSTOMER_v1_1">
  <inertial>
    <origin xyz="0.010207547124739258 0.015485878656815472 0.004902567609673003" rpy="0 0 0"/>
    <mass value="0.07101056528211638"/>
    <inertia ixx="8e-06" iyy="7e-06" izz="1.4e-05" ixy="-4e-06" iyz="-0.0" ixz="-0.0"/>
  </inertial>
  <visual>
    <origin xyz="-0.336942 0.183456 -2.047855" rpy="0 0 0"/>
    <geometry>
      <mesh filename="package://kmr_iiwa_gripkit_cr_plus_l_dd_description/meshes/BE_20-030_CUSTOMER_v1_1.stl" scale="0.001 0.001 0.001"/>
    </geometry>
    <material name="silver"/>
  </visual>
  <collision>
    <origin xyz="-0.336942 0.183456 -2.047855" rpy="0 0 0"/>
    <geometry>
      <mesh filename="package://kmr_iiwa_gripkit_cr_plus_l_dd_description/meshes/BE_20-030_CUSTOMER_v1_1.stl" scale="0.001 0.001 0.001"/>
    </geometry>
  </collision>
</link>

<link name="BE_20-030_CUSTOMER_v1__1__1">
  <inertial>
    <origin xyz="-0.010206831130437022 -0.015485862266345851 0.004902567609673003" rpy="0 0 0"/>
    <mass value="0.07101056528211638"/>
    <inertia ixx="8e-06" iyy="7e-06" izz="1.4e-05" ixy="-4e-06" iyz="0.0" ixz="0.0"/>
  </inertial>
  <visual>
    <origin xyz="-0.373942 0.187456 -2.047855" rpy="0 0 0"/>
    <geometry>
      <mesh filename="package://kmr_iiwa_gripkit_cr_plus_l_dd_description/meshes/BE_20-030_CUSTOMER_v1__1__1.stl" scale="0.001 0.001 0.001"/>
    </geometry>
    <material name="silver"/>
  </visual>
  <collision>
    <origin xyz="-0.373942 0.187456 -2.047855" rpy="0 0 0"/>
    <geometry>
      <mesh filename="package://kmr_iiwa_gripkit_cr_plus_l_dd_description/meshes/BE_20-030_CUSTOMER_v1__1__1.stl" scale="0.001 0.001 0.001"/>
    </geometry>
  </collision>
</link>

<link name="FE_20-050_CUSTOMER_v1_1">
  <inertial>
    <origin xyz="3.5799715114581687e-07 0.024908415860821764 6.722884599552614e-05" rpy="0 0 0"/>
    <mass value="0.11001397809346045"/>
    <inertia ixx="4.5e-05" iyy="8e-06" izz="4.4e-05" ixy="-0.0" iyz="7e-06" ixz="0.0"/>
  </inertial>
  <visual>
    <origin xyz="-0.355442 0.158456 -2.057855" rpy="0 0 0"/>
    <geometry>
      <mesh filename="package://kmr_iiwa_gripkit_cr_plus_l_dd_description/meshes/FE_20-050_CUSTOMER_v1_1.stl" scale="0.001 0.001 0.001"/>
    </geometry>
    <material name="silver"/>
  </visual>
  <collision>
    <origin xyz="-0.355442 0.158456 -2.057855" rpy="0 0 0"/>
    <geometry>
      <mesh filename="package://kmr_iiwa_gripkit_cr_plus_l_dd_description/meshes/FE_20-050_CUSTOMER_v1_1.stl" scale="0.001 0.001 0.001"/>
    </geometry>
  </collision>
</link>

<link name="FE_20-050_CUSTOMER_v1__1__1">
  <inertial>
    <origin xyz="3.5799715114581687e-07 -0.024908399470353254 6.722884599552614e-05" rpy="0 0 0"/>
    <mass value="0.11001397809346045"/>
    <inertia ixx="4.5e-05" iyy="8e-06" izz="4.4e-05" ixy="-0.0" iyz="-7e-06" ixz="0.0"/>
  </inertial>
  <visual>
    <origin xyz="-0.355442 0.212456 -2.057855" rpy="0 0 0"/>
    <geometry>
      <mesh filename="package://kmr_iiwa_gripkit_cr_plus_l_dd_description/meshes/FE_20-050_CUSTOMER_v1__1__1.stl" scale="0.001 0.001 0.001"/>
    </geometry>
    <material name="silver"/>
  </visual>
  <collision>
    <origin xyz="-0.355442 0.212456 -2.057855" rpy="0 0 0"/>
    <geometry>
      <mesh filename="package://kmr_iiwa_gripkit_cr_plus_l_dd_description/meshes/FE_20-050_CUSTOMER_v1__1__1.stl" scale="0.001 0.001 0.001"/>
    </geometry>
  </collision>
</link>

<link name="AC_20-025_CUSTOMER_v1_1">
  <inertial>
    <origin xyz="3.5799715114581687e-07 0.001943768229512699 0.01432793711417979" rpy="0 0 0"/>
    <mass value="0.07018824497649055"/>
    <inertia ixx="9e-06" iyy="9e-06" izz="4e-06" ixy="-0.0" iyz="-1e-06" ixz="-0.0"/>
  </inertial>
  <visual>
    <origin xyz="-0.355442 0.108456 -2.057855" rpy="0 0 0"/>
    <geometry>
      <mesh filename="package://kmr_iiwa_gripkit_cr_plus_l_dd_description/meshes/AC_20-025_CUSTOMER_v1_1.stl" scale="0.001 0.001 0.001"/>
    </geometry>
    <material name="silver"/>
  </visual>
  <collision>
    <origin xyz="-0.355442 0.108456 -2.057855" rpy="0 0 0"/>
    <geometry>
      <mesh filename="package://kmr_iiwa_gripkit_cr_plus_l_dd_description/meshes/AC_20-025_CUSTOMER_v1_1.stl" scale="0.001 0.001 0.001"/>
    </geometry>
  </collision>
</link>

<link name="AC_20-025_CUSTOMER_v1__1__1">
  <inertial>
    <origin xyz="3.5799715114581687e-07 -0.0019437518390421071 0.01432793711417979" rpy="0 0 0"/>
    <mass value="0.07018824497649055"/>
    <inertia ixx="9e-06" iyy="9e-06" izz="4e-06" ixy="0.0" iyz="1e-06" ixz="0.0"/>
  </inertial>
  <visual>
    <origin xyz="-0.355442 0.262456 -2.057855" rpy="0 0 0"/>
    <geometry>
      <mesh filename="package://kmr_iiwa_gripkit_cr_plus_l_dd_description/meshes/AC_20-025_CUSTOMER_v1__1__1.stl" scale="0.001 0.001 0.001"/>
    </geometry>
    <material name="silver"/>
  </visual>
  <collision>
    <origin xyz="-0.355442 0.262456 -2.057855" rpy="0 0 0"/>
    <geometry>
      <mesh filename="package://kmr_iiwa_gripkit_cr_plus_l_dd_description/meshes/AC_20-025_CUSTOMER_v1__1__1.stl" scale="0.001 0.001 0.001"/>
    </geometry>
  </collision>
</link>

<link name="FT_20-UNI_CUSTOMER_v1_1">
  <inertial>
    <origin xyz="3.579971288303341e-07 -0.009778998941201725 6.0014871332558783e-05" rpy="0 0 0"/>
    <mass value="0.05314853137521012"/>
    <inertia ixx="3e-06" iyy="3e-06" izz="3e-06" ixy="0.0" iyz="0.0" ixz="0.0"/>
  </inertial>
  <visual>
    <origin xyz="-0.355442 0.108456 -2.082855" rpy="0 0 0"/>
    <geometry>
      <mesh filename="package://kmr_iiwa_gripkit_cr_plus_l_dd_description/meshes/FT_20-UNI_CUSTOMER_v1_1.stl" scale="0.001 0.001 0.001"/>
    </geometry>
    <material name="silver"/>
  </visual>
  <collision>
    <origin xyz="-0.355442 0.108456 -2.082855" rpy="0 0 0"/>
    <geometry>
      <mesh filename="package://kmr_iiwa_gripkit_cr_plus_l_dd_description/meshes/FT_20-UNI_CUSTOMER_v1_1.stl" scale="0.001 0.001 0.001"/>
    </geometry>
  </collision>
</link>

<link name="FT_20-UNI_CUSTOMER_v1__1__1">
  <inertial>
    <origin xyz="3.5799717346129967e-07 0.009779015331673635 6.0014871331226516e-05" rpy="0 0 0"/>
    <mass value="0.05314853137521012"/>
    <inertia ixx="3e-06" iyy="3e-06" izz="3e-06" ixy="0.0" iyz="-0.0" ixz="-0.0"/>
  </inertial>
  <visual>
    <origin xyz="-0.355442 0.262456 -2.082855" rpy="0 0 0"/>
    <geometry>
      <mesh filename="package://kmr_iiwa_gripkit_cr_plus_l_dd_description/meshes/FT_20-UNI_CUSTOMER_v1__1__1.stl" scale="0.001 0.001 0.001"/>
    </geometry>
    <material name="silver"/>
  </visual>
  <collision>
    <origin xyz="-0.355442 0.262456 -2.082855" rpy="0 0 0"/>
    <geometry>
      <mesh filename="package://kmr_iiwa_gripkit_cr_plus_l_dd_description/meshes/FT_20-UNI_CUSTOMER_v1__1__1.stl" scale="0.001 0.001 0.001"/>
    </geometry>
  </collision>
</link>

<link name="link_1_1">
  <inertial>
    <origin xyz="-0.03473315224028228 -8.795479405909745e-08 0.12351570882429563" rpy="0 0 0"/>
    <mass value="21.213888253656222"/>
    <inertia ixx="0.127957" iyy="0.13413" izz="0.047327" ixy="-0.0" iyz="-0.0" ixz="0.023881"/>
  </inertial>
  <visual>
    <origin xyz="-0.355642 0.185456 -0.847855" rpy="0 0 0"/>
    <geometry>
      <mesh filename="package://kmr_iiwa_gripkit_cr_plus_l_dd_description/meshes/link_1_1.stl" scale="0.001 0.001 0.001"/>
    </geometry>
    <material name="silver"/>
  </visual>
  <collision>
    <origin xyz="-0.355642 0.185456 -0.847855" rpy="0 0 0"/>
    <geometry>
      <mesh filename="package://kmr_iiwa_gripkit_cr_plus_l_dd_description/meshes/link_1_1.stl" scale="0.001 0.001 0.001"/>
    </geometry>
  </collision>
</link>

<link name="link_2_1">
  <inertial>
    <origin xyz="0.04491547984812577 -4.5766725825791e-08 0.06732512301271631" rpy="0 0 0"/>
    <mass value="21.397098230942653"/>
    <inertia ixx="0.127529" iyy="0.133838" izz="0.047851" ixy="0.0" iyz="-0.0" ixz="0.02227"/>
  </inertial>
  <visual>
    <origin xyz="-0.345142 0.185456 -1.040855" rpy="0 0 0"/>
    <geometry>
      <mesh filename="package://kmr_iiwa_gripkit_cr_plus_l_dd_description/meshes/link_2_1.stl" scale="0.001 0.001 0.001"/>
    </geometry>
    <material name="silver"/>
  </visual>
  <collision>
    <origin xyz="-0.345142 0.185456 -1.040855" rpy="0 0 0"/>
    <geometry>
      <mesh filename="package://kmr_iiwa_gripkit_cr_plus_l_dd_description/meshes/link_2_1.stl" scale="0.001 0.001 0.001"/>
    </geometry>
  </collision>
</link>

<link name="link_3_1">
  <inertial>
    <origin xyz="0.02956404415924141 -3.877012377806466e-09 0.1365030882646392" rpy="0 0 0"/>
    <mass value="24.923668408341197"/>
    <inertia ixx="0.186887" iyy="0.196866" izz="0.059721" ixy="0.0" iyz="0.0" ixz="-0.038259"/>
  </inertial>
  <visual>
    <origin xyz="-0.355642 0.185456 -1.215355" rpy="0 0 0"/>
    <geometry>
      <mesh filename="package://kmr_iiwa_gripkit_cr_plus_l_dd_description/meshes/link_3_1.stl" scale="0.001 0.001 0.001"/>
    </geometry>
    <material name="silver"/>
  </visual>
  <collision>
    <origin xyz="-0.355642 0.185456 -1.215355" rpy="0 0 0"/>
    <geometry>
      <mesh filename="package://kmr_iiwa_gripkit_cr_plus_l_dd_description/meshes/link_3_1.stl" scale="0.001 0.001 0.001"/>
    </geometry>
  </collision>
</link>

<link name="link_4_1">
  <inertial>
    <origin xyz="-0.04491538211444518 6.304607769180848e-08 0.06732495102622416" rpy="0 0 0"/>
    <mass value="21.397084006482324"/>
    <inertia ixx="0.127521" iyy="0.133811" izz="0.047832" ixy="-0.0" iyz="0.0" ixz="-0.022267"/>
  </inertial>
  <visual>
    <origin xyz="-0.366142 0.185456 -1.440855" rpy="0 0 0"/>
    <geometry>
      <mesh filename="package://kmr_iiwa_gripkit_cr_plus_l_dd_description/meshes/link_4_1.stl" scale="0.001 0.001 0.001"/>
    </geometry>
    <material name="silver"/>
  </visual>
  <collision>
    <origin xyz="-0.366142 0.185456 -1.440855" rpy="0 0 0"/>
    <geometry>
      <mesh filename="package://kmr_iiwa_gripkit_cr_plus_l_dd_description/meshes/link_4_1.stl" scale="0.001 0.001 0.001"/>
    </geometry>
  </collision>
</link>

<link name="link_5_1">
  <inertial>
    <origin xyz="-0.021386232316168985 1.7030018534258673e-08 0.08546808558254848" rpy="0 0 0"/>
    <mass value="13.296685148643036"/>
    <inertia ixx="0.068318" iyy="0.079123" izz="0.035085" ixy="0.0" iyz="-0.0" ixz="0.024261"/>
  </inertial>
  <visual>
    <origin xyz="-0.355642 0.185456 -1.615355" rpy="0 0 0"/>
    <geometry>
      <mesh filename="package://kmr_iiwa_gripkit_cr_plus_l_dd_description/meshes/link_5_1.stl" scale="0.001 0.001 0.001"/>
    </geometry>
    <material name="silver"/>
  </visual>
  <collision>
    <origin xyz="-0.355642 0.185456 -1.615355" rpy="0 0 0"/>
    <geometry>
      <mesh filename="package://kmr_iiwa_gripkit_cr_plus_l_dd_description/meshes/link_5_1.stl" scale="0.001 0.001 0.001"/>
    </geometry>
  </collision>
</link>

<link name="link_6_1">
  <inertial>
    <origin xyz="0.07098724287792602 2.865957765829652e-07 0.0021151653285145233" rpy="0 0 0"/>
    <mass value="14.421198781272748"/>
    <inertia ixx="0.038461" iyy="0.040001" izz="0.027817" ixy="-0.0" iyz="-0.0" ixz="0.00196"/>
  </inertial>
  <visual>
    <origin xyz="-0.284942 0.185456 -1.840855" rpy="0 0 0"/>
    <geometry>
      <mesh filename="package://kmr_iiwa_gripkit_cr_plus_l_dd_description/meshes/link_6_1.stl" scale="0.001 0.001 0.001"/>
    </geometry>
    <material name="silver"/>
  </visual>
  <collision>
    <origin xyz="-0.284942 0.185456 -1.840855" rpy="0 0 0"/>
    <geometry>
      <mesh filename="package://kmr_iiwa_gripkit_cr_plus_l_dd_description/meshes/link_6_1.stl" scale="0.001 0.001 0.001"/>
    </geometry>
  </collision>
</link>

<link name="flange_1">
  <inertial>
    <origin xyz="3.752888053099035e-07 -4.650858910631994e-06 0.009981401746486984" rpy="0 0 0"/>
    <mass value="2.1030620192288976"/>
    <inertia ixx="0.001534" iyy="0.001534" izz="0.00251" ixy="1.5e-05" iyz="0.0" ixz="-0.0"/>
  </inertial>
  <visual>
    <origin xyz="-0.355442 0.185456 -1.931755" rpy="0 0 0"/>
    <geometry>
      <mesh filename="package://kmr_iiwa_gripkit_cr_plus_l_dd_description/meshes/flange_1.stl" scale="0.001 0.001 0.001"/>
    </geometry>
    <material name="silver"/>
  </visual>
  <collision>
    <origin xyz="-0.355442 0.185456 -1.931755" rpy="0 0 0"/>
    <geometry>
      <mesh filename="package://kmr_iiwa_gripkit_cr_plus_l_dd_description/meshes/flange_1.stl" scale="0.001 0.001 0.001"/>
    </geometry>
  </collision>
</link>

<link name="link_0_1">
  <inertial>
    <origin xyz="3.123595955778491e-07 0.01283243923600072 0.06810381029435741" rpy="0 0 0"/>
    <mass value="30.321448900186642"/>
    <inertia ixx="0.139451" iyy="0.111656" izz="0.133146" ixy="0.0" iyz="-0.004809" ixz="-0.0"/>
  </inertial>
  <visual>
    <origin xyz="-0.355642 0.185456 -0.702355" rpy="0 0 0"/>
    <geometry>
      <mesh filename="package://kmr_iiwa_gripkit_cr_plus_l_dd_description/meshes/link_0_1.stl" scale="0.001 0.001 0.001"/>
    </geometry>
    <material name="silver"/>
  </visual>
  <collision>
    <origin xyz="-0.355642 0.185456 -0.702355" rpy="0 0 0"/>
    <geometry>
      <mesh filename="package://kmr_iiwa_gripkit_cr_plus_l_dd_description/meshes/link_0_1.stl" scale="0.001 0.001 0.001"/>
    </geometry>
  </collision>
</link>

<joint name="base_footprint_joint" type="fixed">
  <origin xyz="0 0 0" rpy="0 0 0"/>
  <parent link="base_footprint"/>
  <child link="base_link"/>
</joint>

<joint name="Rigid1" type="fixed">
  <origin xyz="0.532642 -0.001456 0.642155" rpy="0 0 0"/>
  <parent link="base_link"/>
  <child link="cover_1"/>
</joint>

<joint name="Rigid18" type="fixed">
  <origin xyz="-0.050301 5e-06 0.01703" rpy="0 0 0"/>
  <parent link="flange_1"/>
  <child link="screw_1_1"/>
</joint>

<joint name="Rigid19" type="fixed">
  <origin xyz="-1e-06 0.050305 0.01703" rpy="0 0 0"/>
  <parent link="flange_1"/>
  <child link="screw_2_1"/>
</joint>

<joint name="Rigid20" type="fixed">
  <origin xyz="0.050299 5e-06 0.01703" rpy="0 0 0"/>
  <parent link="flange_1"/>
  <child link="screw_3_1"/>
</joint>

<joint name="Rigid21" type="fixed">
  <origin xyz="-1e-06 -0.050295 0.01703" rpy="0 0 0"/>
  <parent link="flange_1"/>
  <child link="screw_4_1"/>
</joint>

<joint name="Rigid22" type="fixed">
  <origin xyz="-0.035567 -0.035567 0.0121" rpy="0 0 0"/>
  <parent link="flange_1"/>
  <child link="screw_5_1"/>
</joint>

<joint name="Rigid23" type="fixed">
  <origin xyz="0.035568 0.035567 0.0121" rpy="0 0 0"/>
  <parent link="flange_1"/>
  <child link="screw_6_1"/>
</joint>

<joint name="Rigid24" type="fixed">
  <origin xyz="-0.025 0.0 0.0351" rpy="0 0 0"/>
  <parent link="flange_1"/>
  <child link="SF-ISO50-CRG200_Customer_1"/>
</joint>

<joint name="Rigid25" type="fixed">
  <origin xyz="0.0015 -0.046 0.011" rpy="0 0 0"/>
  <parent link="SF-ISO50-CRG200_Customer_1"/>
  <child link="CRG200_body_1"/>
</joint>

<joint name="Slider26" type="prismatic">
  <origin xyz="0.005 0.046 0.0576" rpy="0 0 0"/>
  <parent link="CRG200_body_1"/>
  <child link="CRG200_base_jaw_1"/>
  <axis xyz="0.0 -1.0 0.0"/>
  <limit upper="0.021" lower="-0.021" effort="100" velocity="100"/>
</joint>

<joint name="Slider27" type="prismatic">
  <origin xyz="0.042 0.046 0.0576" rpy="0 0 0"/>
  <parent link="CRG200_body_1"/>
  <child link="CRG200_base_jaw__1__1"/>
  <axis xyz="0.0 -1.0 0.0"/>
  <limit upper="0.021" lower="-0.021" effort="100" velocity="100"/>
</joint>

<joint name="Rigid28" type="fixed">
  <origin xyz="0.0235 0.046 0.0601" rpy="0 0 0"/>
  <parent link="CRG200_body_1"/>
  <child link="CRG200_top_cover_1"/>
</joint>

<joint name="Rigid29" type="fixed">
  <origin xyz="0.0015 0.046 0.0065" rpy="0 0 0"/>
  <parent link="SF-ISO50-CRG200_Customer_1"/>
  <child link="ISO_4762_-_M4_x_12ISO_1"/>
</joint>

<joint name="Rigid30" type="fixed">
  <origin xyz="0.0015 -0.046 0.0065" rpy="0 0 0"/>
  <parent link="SF-ISO50-CRG200_Customer_1"/>
  <child link="ISO_4762_-_M4_x_12ISO__1__1"/>
</joint>

<joint name="Rigid31" type="fixed">
  <origin xyz="0.0485 -0.046 0.0065" rpy="0 0 0"/>
  <parent link="SF-ISO50-CRG200_Customer_1"/>
  <child link="ISO_4762_-_M4_x_12ISO__2__1"/>
</joint>

<joint name="Rigid32" type="fixed">
  <origin xyz="0.0485 0.046 0.0065" rpy="0 0 0"/>
  <parent link="SF-ISO50-CRG200_Customer_1"/>
  <child link="ISO_4762_-_M4_x_12ISO__3__1"/>
</joint>

<joint name="Rigid33" type="fixed">
  <origin xyz="0.0 0.002 0.0124" rpy="0 0 0"/>
  <parent link="CRG200_base_jaw_1"/>
  <child link="BE_20-030_CUSTOMER_v1_1"/>
</joint>

<joint name="Rigid34" type="fixed">
  <origin xyz="0.0 -0.002 0.0124" rpy="0 0 0"/>
  <parent link="CRG200_base_jaw__1__1"/>
  <child link="BE_20-030_CUSTOMER_v1__1__1"/>
</joint>

<joint name="Rigid35" type="fixed">
  <origin xyz="0.0185 0.025 0.01" rpy="0 0 0"/>
  <parent link="BE_20-030_CUSTOMER_v1_1"/>
  <child link="FE_20-050_CUSTOMER_v1_1"/>
</joint>

<joint name="Rigid36" type="fixed">
  <origin xyz="-0.0185 -0.025 0.01" rpy="0 0 0"/>
  <parent link="BE_20-030_CUSTOMER_v1__1__1"/>
  <child link="FE_20-050_CUSTOMER_v1__1__1"/>
</joint>

<joint name="Rigid37" type="fixed">
  <origin xyz="0.0 0.05 0.0" rpy="0 0 0"/>
  <parent link="FE_20-050_CUSTOMER_v1_1"/>
  <child link="AC_20-025_CUSTOMER_v1_1"/>
</joint>

<joint name="Rigid38" type="fixed">
  <origin xyz="0.0 -0.05 0.0" rpy="0 0 0"/>
  <parent link="FE_20-050_CUSTOMER_v1__1__1"/>
  <child link="AC_20-025_CUSTOMER_v1__1__1"/>
</joint>

<joint name="Rigid39" type="fixed">
  <origin xyz="0.0 0.0 0.025" rpy="0 0 0"/>
  <parent link="AC_20-025_CUSTOMER_v1_1"/>
  <child link="FT_20-UNI_CUSTOMER_v1_1"/>
</joint>

<joint name="Rigid40" type="fixed">
  <origin xyz="0.0 0.0 0.025" rpy="0 0 0"/>
  <parent link="AC_20-025_CUSTOMER_v1__1__1"/>
  <child link="FT_20-UNI_CUSTOMER_v1__1__1"/>
</joint>

<joint name="Rev41" type="revolute">
  <origin xyz="0.0 0.0 0.1455" rpy="0 0 0"/>
  <parent link="link_0_1"/>
  <child link="link_1_1"/>
  <axis xyz="-0.0 -0.0 1.0"/>
  <limit upper="2.96706" lower="-2.96706" effort="100" velocity="100"/>
</joint>

<joint name="Rev42" type="revolute">
  <origin xyz="-0.0105 0.0 0.193" rpy="0 0 0"/>
  <parent link="link_1_1"/>
  <child link="link_2_1"/>
  <axis xyz="1.0 -0.0 0.0"/>
  <limit upper="2.094395" lower="-2.094395" effort="100" velocity="100"/>
</joint>

<joint name="Rev43" type="revolute">
  <origin xyz="0.0105 0.0 0.1745" rpy="0 0 0"/>
  <parent link="link_2_1"/>
  <child link="link_3_1"/>
  <axis xyz="-0.0 -0.0 1.0"/>
  <limit upper="2.96706" lower="-2.96706" effort="100" velocity="100"/>
</joint>

<joint name="Rev44" type="revolute">
  <origin xyz="0.0105 0.0 0.2255" rpy="0 0 0"/>
  <parent link="link_3_1"/>
  <child link="link_4_1"/>
  <axis xyz="-1.0 0.0 -0.0"/>
  <limit upper="2.094395" lower="-2.094395" effort="100" velocity="100"/>
</joint>

<joint name="Rev45" type="revolute">
  <origin xyz="-0.0105 0.0 0.1745" rpy="0 0 0"/>
  <parent link="link_4_1"/>
  <child link="link_5_1"/>
  <axis xyz="-0.0 -0.0 1.0"/>
  <limit upper="2.96706" lower="-2.96706" effort="100" velocity="100"/>
</joint>

<joint name="Rev46" type="revolute">
  <origin xyz="-0.0707 0.0 0.2255" rpy="0 0 0"/>
  <parent link="link_5_1"/>
  <child link="link_6_1"/>
  <axis xyz="1.0 -0.0 0.0"/>
  <limit upper="2.094395" lower="-2.094395" effort="100" velocity="100"/>
</joint>

<joint name="Rev47" type="revolute">
  <origin xyz="0.0705 0.0 0.0909" rpy="0 0 0"/>
  <parent link="link_6_1"/>
  <child link="flange_1"/>
  <axis xyz="-0.0 -0.0 1.0"/>
  <limit upper="3.054326" lower="-3.054326" effort="100" velocity="100"/>
</joint>

<joint name="Rigid48" type="fixed">
  <origin xyz="0.355642 -0.185456 0.702355" rpy="0 0 0"/>
  <parent link="base_link"/>
  <child link="link_0_1"/>
</joint>

</robot>
